2025-02-06 11:20:41,777 - INFO - Start polling
2025-02-06 11:20:41,981 - INFO - Run polling for bot @Gamma_M_machines_information_Bot id=7735807460 - 'Gamma_M information about the machines'
2025-02-06 11:20:42,789 - ERROR - Ошибка при отправке сообщения: name 'machine_keyboard' is not defined
2025-02-06 11:20:42,789 - INFO - Update id=619412422 is handled. Duration 718 ms by bot id=7735807460
2025-02-06 11:20:42,821 - ERROR - Ошибка при отправке сообщения: name 'machine_keyboard' is not defined
2025-02-06 11:20:42,822 - INFO - Update id=619412423 is handled. Duration 750 ms by bot id=7735807460
2025-02-06 11:20:42,859 - ERROR - Ошибка при отправке сообщения: name 'machine_keyboard' is not defined
2025-02-06 11:20:42,859 - INFO - Update id=619412424 is handled. Duration 781 ms by bot id=7735807460
2025-02-06 11:20:42,889 - ERROR - Ошибка при отправке сообщения: name 'machine_keyboard' is not defined
2025-02-06 11:20:42,889 - INFO - Update id=619412425 is handled. Duration 812 ms by bot id=7735807460
2025-02-06 11:20:42,929 - ERROR - Ошибка при отправке сообщения: name 'machine_keyboard' is not defined
2025-02-06 11:20:42,929 - INFO - Update id=619412426 is handled. Duration 860 ms by bot id=7735807460
2025-02-06 11:36:20,966 - INFO - Start polling
2025-02-06 11:36:21,166 - INFO - Run polling for bot @Gamma_M_machines_information_Bot id=7735807460 - 'Gamma_M information about the machines'
2025-02-06 11:36:22,111 - INFO - Пользователь 857663686 выбрал опцию: Цех 1
2025-02-06 11:36:22,112 - INFO - Update id=619412427 is handled. Duration 844 ms by bot id=7735807460
2025-02-06 11:36:22,113 - INFO - Пользователь 857663686 выбрал опцию: Цех 1
2025-02-06 11:36:22,113 - INFO - Update id=619412428 is handled. Duration 844 ms by bot id=7735807460
2025-02-06 11:36:27,656 - INFO - Пользователь 857663686 выбрал опцию: Цех 1
2025-02-06 11:36:27,656 - INFO - Update id=619412429 is handled. Duration 171 ms by bot id=7735807460
2025-02-06 11:36:28,966 - ERROR - Ошибка при чтении файла: [Errno 2] No such file or directory: 'Machine_info.txt'
2025-02-06 11:36:28,966 - INFO - Update id=619412430 is handled. Duration 0 ms by bot id=7735807460
2025-02-06 11:36:30,090 - ERROR - Ошибка при чтении файла: [Errno 2] No such file or directory: 'Machine_info.txt'
2025-02-06 11:36:30,090 - INFO - Update id=619412431 is handled. Duration 0 ms by bot id=7735807460
2025-02-06 11:49:45,261 - INFO - Start polling
2025-02-06 11:49:45,468 - INFO - Run polling for bot @Gamma_M_machines_information_Bot id=7735807460 - 'Gamma_M information about the machines'
2025-02-06 11:49:46,296 - INFO - Пользователь 857663686 выбрал опцию: Цех 1
2025-02-06 11:49:46,297 - INFO - Update id=619412432 is handled. Duration 750 ms by bot id=7735807460
2025-02-06 11:49:48,008 - INFO - Update id=619412433 is not handled. Duration 155 ms by bot id=7735807460
2025-02-06 11:49:48,008 - ERROR - Cause exception while process update id=619412433 by bot id=7735807460
ValidationError: 1 validation error for EditMessageText
reply_markup
  Input should be a valid dictionary or instance of InlineKeyboardMarkup [type=model_type, input_value=ReplyKeyboardMarkup(keybo...er=None, selective=None), input_type=ReplyKeyboardMarkup]
    For further information visit https://errors.pydantic.dev/2.10/v/model_type
Traceback (most recent call last):
  File "C:\Users\комп\AppData\Local\Programs\Python\Python310\lib\site-packages\aiogram\dispatcher\dispatcher.py", line 309, in _process_update
    response = await self.feed_update(bot, update, **kwargs)
  File "C:\Users\комп\AppData\Local\Programs\Python\Python310\lib\site-packages\aiogram\dispatcher\dispatcher.py", line 158, in feed_update
    response = await self.update.wrap_outer_middleware(
  File "C:\Users\комп\AppData\Local\Programs\Python\Python310\lib\site-packages\aiogram\dispatcher\middlewares\error.py", line 25, in __call__
    return await handler(event, data)
  File "C:\Users\комп\AppData\Local\Programs\Python\Python310\lib\site-packages\aiogram\dispatcher\middlewares\user_context.py", line 56, in __call__
    return await handler(event, data)
  File "C:\Users\комп\AppData\Local\Programs\Python\Python310\lib\site-packages\aiogram\fsm\middleware.py", line 42, in __call__
    return await handler(event, data)
  File "C:\Users\комп\AppData\Local\Programs\Python\Python310\lib\site-packages\aiogram\dispatcher\event\telegram.py", line 121, in trigger
    return await wrapped_inner(event, kwargs)
  File "C:\Users\комп\AppData\Local\Programs\Python\Python310\lib\site-packages\aiogram\dispatcher\event\handler.py", line 43, in call
    return await wrapped()
  File "C:\Users\комп\AppData\Local\Programs\Python\Python310\lib\site-packages\aiogram\dispatcher\dispatcher.py", line 276, in _listen_update
    return await self.propagate_event(update_type=update_type, event=event, **kwargs)
  File "C:\Users\комп\AppData\Local\Programs\Python\Python310\lib\site-packages\aiogram\dispatcher\router.py", line 146, in propagate_event
    return await observer.wrap_outer_middleware(_wrapped, event=event, data=kwargs)
  File "C:\Users\комп\AppData\Local\Programs\Python\Python310\lib\site-packages\aiogram\dispatcher\router.py", line 141, in _wrapped
    return await self._propagate_event(
  File "C:\Users\комп\AppData\Local\Programs\Python\Python310\lib\site-packages\aiogram\dispatcher\router.py", line 166, in _propagate_event
    response = await observer.trigger(event, **kwargs)
  File "C:\Users\комп\AppData\Local\Programs\Python\Python310\lib\site-packages\aiogram\dispatcher\event\telegram.py", line 121, in trigger
    return await wrapped_inner(event, kwargs)
  File "C:\Users\комп\AppData\Local\Programs\Python\Python310\lib\site-packages\aiogram\dispatcher\event\handler.py", line 43, in call
    return await wrapped()
  File "c:\Users\комп\Desktop\Gamma_m_Project\Gamma_M_infoBot\main.py", line 148, in back_to_workshop
    await call.message.edit_text('Выберите цех:', reply_markup=start_keyboard)
  File "C:\Users\комп\AppData\Local\Programs\Python\Python310\lib\site-packages\aiogram\types\message.py", line 3670, in edit_text
    return EditMessageText(
  File "C:\Users\комп\AppData\Local\Programs\Python\Python310\lib\site-packages\pydantic\main.py", line 214, in __init__
    validated_self = self.__pydantic_validator__.validate_python(data, self_instance=self)
pydantic_core._pydantic_core.ValidationError: 1 validation error for EditMessageText
reply_markup
  Input should be a valid dictionary or instance of InlineKeyboardMarkup [type=model_type, input_value=ReplyKeyboardMarkup(keybo...er=None, selective=None), input_type=ReplyKeyboardMarkup]
    For further information visit https://errors.pydantic.dev/2.10/v/model_type
2025-02-06 11:49:49,735 - INFO - Update id=619412434 is not handled. Duration 63 ms by bot id=7735807460
2025-02-06 11:49:49,735 - ERROR - Cause exception while process update id=619412434 by bot id=7735807460
ValidationError: 1 validation error for EditMessageText
reply_markup
  Input should be a valid dictionary or instance of InlineKeyboardMarkup [type=model_type, input_value=ReplyKeyboardMarkup(keybo...er=None, selective=None), input_type=ReplyKeyboardMarkup]
    For further information visit https://errors.pydantic.dev/2.10/v/model_type
Traceback (most recent call last):
  File "C:\Users\комп\AppData\Local\Programs\Python\Python310\lib\site-packages\aiogram\dispatcher\dispatcher.py", line 309, in _process_update
    response = await self.feed_update(bot, update, **kwargs)
  File "C:\Users\комп\AppData\Local\Programs\Python\Python310\lib\site-packages\aiogram\dispatcher\dispatcher.py", line 158, in feed_update
    response = await self.update.wrap_outer_middleware(
  File "C:\Users\комп\AppData\Local\Programs\Python\Python310\lib\site-packages\aiogram\dispatcher\middlewares\error.py", line 25, in __call__
    return await handler(event, data)
  File "C:\Users\комп\AppData\Local\Programs\Python\Python310\lib\site-packages\aiogram\dispatcher\middlewares\user_context.py", line 56, in __call__
    return await handler(event, data)
  File "C:\Users\комп\AppData\Local\Programs\Python\Python310\lib\site-packages\aiogram\fsm\middleware.py", line 42, in __call__
    return await handler(event, data)
  File "C:\Users\комп\AppData\Local\Programs\Python\Python310\lib\site-packages\aiogram\dispatcher\event\telegram.py", line 121, in trigger
    return await wrapped_inner(event, kwargs)
  File "C:\Users\комп\AppData\Local\Programs\Python\Python310\lib\site-packages\aiogram\dispatcher\event\handler.py", line 43, in call
    return await wrapped()
  File "C:\Users\комп\AppData\Local\Programs\Python\Python310\lib\site-packages\aiogram\dispatcher\dispatcher.py", line 276, in _listen_update
    return await self.propagate_event(update_type=update_type, event=event, **kwargs)
  File "C:\Users\комп\AppData\Local\Programs\Python\Python310\lib\site-packages\aiogram\dispatcher\router.py", line 146, in propagate_event
    return await observer.wrap_outer_middleware(_wrapped, event=event, data=kwargs)
  File "C:\Users\комп\AppData\Local\Programs\Python\Python310\lib\site-packages\aiogram\dispatcher\router.py", line 141, in _wrapped
    return await self._propagate_event(
  File "C:\Users\комп\AppData\Local\Programs\Python\Python310\lib\site-packages\aiogram\dispatcher\router.py", line 166, in _propagate_event
    response = await observer.trigger(event, **kwargs)
  File "C:\Users\комп\AppData\Local\Programs\Python\Python310\lib\site-packages\aiogram\dispatcher\event\telegram.py", line 121, in trigger
    return await wrapped_inner(event, kwargs)
  File "C:\Users\комп\AppData\Local\Programs\Python\Python310\lib\site-packages\aiogram\dispatcher\event\handler.py", line 43, in call
    return await wrapped()
  File "c:\Users\комп\Desktop\Gamma_m_Project\Gamma_M_infoBot\main.py", line 148, in back_to_workshop
    await call.message.edit_text('Выберите цех:', reply_markup=start_keyboard)
  File "C:\Users\комп\AppData\Local\Programs\Python\Python310\lib\site-packages\aiogram\types\message.py", line 3670, in edit_text
    return EditMessageText(
  File "C:\Users\комп\AppData\Local\Programs\Python\Python310\lib\site-packages\pydantic\main.py", line 214, in __init__
    validated_self = self.__pydantic_validator__.validate_python(data, self_instance=self)
pydantic_core._pydantic_core.ValidationError: 1 validation error for EditMessageText
reply_markup
  Input should be a valid dictionary or instance of InlineKeyboardMarkup [type=model_type, input_value=ReplyKeyboardMarkup(keybo...er=None, selective=None), input_type=ReplyKeyboardMarkup]
    For further information visit https://errors.pydantic.dev/2.10/v/model_type
2025-02-06 11:49:50,240 - INFO - Update id=619412435 is not handled. Duration 63 ms by bot id=7735807460
2025-02-06 11:49:50,240 - ERROR - Cause exception while process update id=619412435 by bot id=7735807460
ValidationError: 1 validation error for EditMessageText
reply_markup
  Input should be a valid dictionary or instance of InlineKeyboardMarkup [type=model_type, input_value=ReplyKeyboardMarkup(keybo...er=None, selective=None), input_type=ReplyKeyboardMarkup]
    For further information visit https://errors.pydantic.dev/2.10/v/model_type
Traceback (most recent call last):
  File "C:\Users\комп\AppData\Local\Programs\Python\Python310\lib\site-packages\aiogram\dispatcher\dispatcher.py", line 309, in _process_update
    response = await self.feed_update(bot, update, **kwargs)
  File "C:\Users\комп\AppData\Local\Programs\Python\Python310\lib\site-packages\aiogram\dispatcher\dispatcher.py", line 158, in feed_update
    response = await self.update.wrap_outer_middleware(
  File "C:\Users\комп\AppData\Local\Programs\Python\Python310\lib\site-packages\aiogram\dispatcher\middlewares\error.py", line 25, in __call__
    return await handler(event, data)
  File "C:\Users\комп\AppData\Local\Programs\Python\Python310\lib\site-packages\aiogram\dispatcher\middlewares\user_context.py", line 56, in __call__
    return await handler(event, data)
  File "C:\Users\комп\AppData\Local\Programs\Python\Python310\lib\site-packages\aiogram\fsm\middleware.py", line 42, in __call__
    return await handler(event, data)
  File "C:\Users\комп\AppData\Local\Programs\Python\Python310\lib\site-packages\aiogram\dispatcher\event\telegram.py", line 121, in trigger
    return await wrapped_inner(event, kwargs)
  File "C:\Users\комп\AppData\Local\Programs\Python\Python310\lib\site-packages\aiogram\dispatcher\event\handler.py", line 43, in call
    return await wrapped()
  File "C:\Users\комп\AppData\Local\Programs\Python\Python310\lib\site-packages\aiogram\dispatcher\dispatcher.py", line 276, in _listen_update
    return await self.propagate_event(update_type=update_type, event=event, **kwargs)
  File "C:\Users\комп\AppData\Local\Programs\Python\Python310\lib\site-packages\aiogram\dispatcher\router.py", line 146, in propagate_event
    return await observer.wrap_outer_middleware(_wrapped, event=event, data=kwargs)
  File "C:\Users\комп\AppData\Local\Programs\Python\Python310\lib\site-packages\aiogram\dispatcher\router.py", line 141, in _wrapped
    return await self._propagate_event(
  File "C:\Users\комп\AppData\Local\Programs\Python\Python310\lib\site-packages\aiogram\dispatcher\router.py", line 166, in _propagate_event
    response = await observer.trigger(event, **kwargs)
  File "C:\Users\комп\AppData\Local\Programs\Python\Python310\lib\site-packages\aiogram\dispatcher\event\telegram.py", line 121, in trigger
    return await wrapped_inner(event, kwargs)
  File "C:\Users\комп\AppData\Local\Programs\Python\Python310\lib\site-packages\aiogram\dispatcher\event\handler.py", line 43, in call
    return await wrapped()
  File "c:\Users\комп\Desktop\Gamma_m_Project\Gamma_M_infoBot\main.py", line 148, in back_to_workshop
    await call.message.edit_text('Выберите цех:', reply_markup=start_keyboard)
  File "C:\Users\комп\AppData\Local\Programs\Python\Python310\lib\site-packages\aiogram\types\message.py", line 3670, in edit_text
    return EditMessageText(
  File "C:\Users\комп\AppData\Local\Programs\Python\Python310\lib\site-packages\pydantic\main.py", line 214, in __init__
    validated_self = self.__pydantic_validator__.validate_python(data, self_instance=self)
pydantic_core._pydantic_core.ValidationError: 1 validation error for EditMessageText
reply_markup
  Input should be a valid dictionary or instance of InlineKeyboardMarkup [type=model_type, input_value=ReplyKeyboardMarkup(keybo...er=None, selective=None), input_type=ReplyKeyboardMarkup]
    For further information visit https://errors.pydantic.dev/2.10/v/model_type
2025-02-06 11:49:50,610 - INFO - Update id=619412436 is not handled. Duration 63 ms by bot id=7735807460
2025-02-06 11:49:50,610 - ERROR - Cause exception while process update id=619412436 by bot id=7735807460
ValidationError: 1 validation error for EditMessageText
reply_markup
  Input should be a valid dictionary or instance of InlineKeyboardMarkup [type=model_type, input_value=ReplyKeyboardMarkup(keybo...er=None, selective=None), input_type=ReplyKeyboardMarkup]
    For further information visit https://errors.pydantic.dev/2.10/v/model_type
Traceback (most recent call last):
  File "C:\Users\комп\AppData\Local\Programs\Python\Python310\lib\site-packages\aiogram\dispatcher\dispatcher.py", line 309, in _process_update
    response = await self.feed_update(bot, update, **kwargs)
  File "C:\Users\комп\AppData\Local\Programs\Python\Python310\lib\site-packages\aiogram\dispatcher\dispatcher.py", line 158, in feed_update
    response = await self.update.wrap_outer_middleware(
  File "C:\Users\комп\AppData\Local\Programs\Python\Python310\lib\site-packages\aiogram\dispatcher\middlewares\error.py", line 25, in __call__
    return await handler(event, data)
  File "C:\Users\комп\AppData\Local\Programs\Python\Python310\lib\site-packages\aiogram\dispatcher\middlewares\user_context.py", line 56, in __call__
    return await handler(event, data)
  File "C:\Users\комп\AppData\Local\Programs\Python\Python310\lib\site-packages\aiogram\fsm\middleware.py", line 42, in __call__
    return await handler(event, data)
  File "C:\Users\комп\AppData\Local\Programs\Python\Python310\lib\site-packages\aiogram\dispatcher\event\telegram.py", line 121, in trigger
    return await wrapped_inner(event, kwargs)
  File "C:\Users\комп\AppData\Local\Programs\Python\Python310\lib\site-packages\aiogram\dispatcher\event\handler.py", line 43, in call
    return await wrapped()
  File "C:\Users\комп\AppData\Local\Programs\Python\Python310\lib\site-packages\aiogram\dispatcher\dispatcher.py", line 276, in _listen_update
    return await self.propagate_event(update_type=update_type, event=event, **kwargs)
  File "C:\Users\комп\AppData\Local\Programs\Python\Python310\lib\site-packages\aiogram\dispatcher\router.py", line 146, in propagate_event
    return await observer.wrap_outer_middleware(_wrapped, event=event, data=kwargs)
  File "C:\Users\комп\AppData\Local\Programs\Python\Python310\lib\site-packages\aiogram\dispatcher\router.py", line 141, in _wrapped
    return await self._propagate_event(
  File "C:\Users\комп\AppData\Local\Programs\Python\Python310\lib\site-packages\aiogram\dispatcher\router.py", line 166, in _propagate_event
    response = await observer.trigger(event, **kwargs)
  File "C:\Users\комп\AppData\Local\Programs\Python\Python310\lib\site-packages\aiogram\dispatcher\event\telegram.py", line 121, in trigger
    return await wrapped_inner(event, kwargs)
  File "C:\Users\комп\AppData\Local\Programs\Python\Python310\lib\site-packages\aiogram\dispatcher\event\handler.py", line 43, in call
    return await wrapped()
  File "c:\Users\комп\Desktop\Gamma_m_Project\Gamma_M_infoBot\main.py", line 148, in back_to_workshop
    await call.message.edit_text('Выберите цех:', reply_markup=start_keyboard)
  File "C:\Users\комп\AppData\Local\Programs\Python\Python310\lib\site-packages\aiogram\types\message.py", line 3670, in edit_text
    return EditMessageText(
  File "C:\Users\комп\AppData\Local\Programs\Python\Python310\lib\site-packages\pydantic\main.py", line 214, in __init__
    validated_self = self.__pydantic_validator__.validate_python(data, self_instance=self)
pydantic_core._pydantic_core.ValidationError: 1 validation error for EditMessageText
reply_markup
  Input should be a valid dictionary or instance of InlineKeyboardMarkup [type=model_type, input_value=ReplyKeyboardMarkup(keybo...er=None, selective=None), input_type=ReplyKeyboardMarkup]
    For further information visit https://errors.pydantic.dev/2.10/v/model_type
2025-02-06 11:49:52,710 - INFO - Update id=619412437 is not handled. Duration 78 ms by bot id=7735807460
2025-02-06 11:49:52,710 - ERROR - Cause exception while process update id=619412437 by bot id=7735807460
ValidationError: 1 validation error for EditMessageText
reply_markup
  Input should be a valid dictionary or instance of InlineKeyboardMarkup [type=model_type, input_value=ReplyKeyboardMarkup(keybo...er=None, selective=None), input_type=ReplyKeyboardMarkup]
    For further information visit https://errors.pydantic.dev/2.10/v/model_type
Traceback (most recent call last):
  File "C:\Users\комп\AppData\Local\Programs\Python\Python310\lib\site-packages\aiogram\dispatcher\dispatcher.py", line 309, in _process_update
    response = await self.feed_update(bot, update, **kwargs)
  File "C:\Users\комп\AppData\Local\Programs\Python\Python310\lib\site-packages\aiogram\dispatcher\dispatcher.py", line 158, in feed_update
    response = await self.update.wrap_outer_middleware(
  File "C:\Users\комп\AppData\Local\Programs\Python\Python310\lib\site-packages\aiogram\dispatcher\middlewares\error.py", line 25, in __call__
    return await handler(event, data)
  File "C:\Users\комп\AppData\Local\Programs\Python\Python310\lib\site-packages\aiogram\dispatcher\middlewares\user_context.py", line 56, in __call__
    return await handler(event, data)
  File "C:\Users\комп\AppData\Local\Programs\Python\Python310\lib\site-packages\aiogram\fsm\middleware.py", line 42, in __call__
    return await handler(event, data)
  File "C:\Users\комп\AppData\Local\Programs\Python\Python310\lib\site-packages\aiogram\dispatcher\event\telegram.py", line 121, in trigger
    return await wrapped_inner(event, kwargs)
  File "C:\Users\комп\AppData\Local\Programs\Python\Python310\lib\site-packages\aiogram\dispatcher\event\handler.py", line 43, in call
    return await wrapped()
  File "C:\Users\комп\AppData\Local\Programs\Python\Python310\lib\site-packages\aiogram\dispatcher\dispatcher.py", line 276, in _listen_update
    return await self.propagate_event(update_type=update_type, event=event, **kwargs)
  File "C:\Users\комп\AppData\Local\Programs\Python\Python310\lib\site-packages\aiogram\dispatcher\router.py", line 146, in propagate_event
    return await observer.wrap_outer_middleware(_wrapped, event=event, data=kwargs)
  File "C:\Users\комп\AppData\Local\Programs\Python\Python310\lib\site-packages\aiogram\dispatcher\router.py", line 141, in _wrapped
    return await self._propagate_event(
  File "C:\Users\комп\AppData\Local\Programs\Python\Python310\lib\site-packages\aiogram\dispatcher\router.py", line 166, in _propagate_event
    response = await observer.trigger(event, **kwargs)
  File "C:\Users\комп\AppData\Local\Programs\Python\Python310\lib\site-packages\aiogram\dispatcher\event\telegram.py", line 121, in trigger
    return await wrapped_inner(event, kwargs)
  File "C:\Users\комп\AppData\Local\Programs\Python\Python310\lib\site-packages\aiogram\dispatcher\event\handler.py", line 43, in call
    return await wrapped()
  File "c:\Users\комп\Desktop\Gamma_m_Project\Gamma_M_infoBot\main.py", line 148, in back_to_workshop
    await call.message.edit_text('Выберите цех:', reply_markup=start_keyboard)
  File "C:\Users\комп\AppData\Local\Programs\Python\Python310\lib\site-packages\aiogram\types\message.py", line 3670, in edit_text
    return EditMessageText(
  File "C:\Users\комп\AppData\Local\Programs\Python\Python310\lib\site-packages\pydantic\main.py", line 214, in __init__
    validated_self = self.__pydantic_validator__.validate_python(data, self_instance=self)
pydantic_core._pydantic_core.ValidationError: 1 validation error for EditMessageText
reply_markup
  Input should be a valid dictionary or instance of InlineKeyboardMarkup [type=model_type, input_value=ReplyKeyboardMarkup(keybo...er=None, selective=None), input_type=ReplyKeyboardMarkup]
    For further information visit https://errors.pydantic.dev/2.10/v/model_type
2025-02-06 11:49:53,463 - INFO - Update id=619412438 is not handled. Duration 78 ms by bot id=7735807460
2025-02-06 11:49:53,463 - ERROR - Cause exception while process update id=619412438 by bot id=7735807460
ValidationError: 1 validation error for EditMessageText
reply_markup
  Input should be a valid dictionary or instance of InlineKeyboardMarkup [type=model_type, input_value=ReplyKeyboardMarkup(keybo...er=None, selective=None), input_type=ReplyKeyboardMarkup]
    For further information visit https://errors.pydantic.dev/2.10/v/model_type
Traceback (most recent call last):
  File "C:\Users\комп\AppData\Local\Programs\Python\Python310\lib\site-packages\aiogram\dispatcher\dispatcher.py", line 309, in _process_update
    response = await self.feed_update(bot, update, **kwargs)
  File "C:\Users\комп\AppData\Local\Programs\Python\Python310\lib\site-packages\aiogram\dispatcher\dispatcher.py", line 158, in feed_update
    response = await self.update.wrap_outer_middleware(
  File "C:\Users\комп\AppData\Local\Programs\Python\Python310\lib\site-packages\aiogram\dispatcher\middlewares\error.py", line 25, in __call__
    return await handler(event, data)
  File "C:\Users\комп\AppData\Local\Programs\Python\Python310\lib\site-packages\aiogram\dispatcher\middlewares\user_context.py", line 56, in __call__
    return await handler(event, data)
  File "C:\Users\комп\AppData\Local\Programs\Python\Python310\lib\site-packages\aiogram\fsm\middleware.py", line 42, in __call__
    return await handler(event, data)
  File "C:\Users\комп\AppData\Local\Programs\Python\Python310\lib\site-packages\aiogram\dispatcher\event\telegram.py", line 121, in trigger
    return await wrapped_inner(event, kwargs)
  File "C:\Users\комп\AppData\Local\Programs\Python\Python310\lib\site-packages\aiogram\dispatcher\event\handler.py", line 43, in call
    return await wrapped()
  File "C:\Users\комп\AppData\Local\Programs\Python\Python310\lib\site-packages\aiogram\dispatcher\dispatcher.py", line 276, in _listen_update
    return await self.propagate_event(update_type=update_type, event=event, **kwargs)
  File "C:\Users\комп\AppData\Local\Programs\Python\Python310\lib\site-packages\aiogram\dispatcher\router.py", line 146, in propagate_event
    return await observer.wrap_outer_middleware(_wrapped, event=event, data=kwargs)
  File "C:\Users\комп\AppData\Local\Programs\Python\Python310\lib\site-packages\aiogram\dispatcher\router.py", line 141, in _wrapped
    return await self._propagate_event(
  File "C:\Users\комп\AppData\Local\Programs\Python\Python310\lib\site-packages\aiogram\dispatcher\router.py", line 166, in _propagate_event
    response = await observer.trigger(event, **kwargs)
  File "C:\Users\комп\AppData\Local\Programs\Python\Python310\lib\site-packages\aiogram\dispatcher\event\telegram.py", line 121, in trigger
    return await wrapped_inner(event, kwargs)
  File "C:\Users\комп\AppData\Local\Programs\Python\Python310\lib\site-packages\aiogram\dispatcher\event\handler.py", line 43, in call
    return await wrapped()
  File "c:\Users\комп\Desktop\Gamma_m_Project\Gamma_M_infoBot\main.py", line 148, in back_to_workshop
    await call.message.edit_text('Выберите цех:', reply_markup=start_keyboard)
  File "C:\Users\комп\AppData\Local\Programs\Python\Python310\lib\site-packages\aiogram\types\message.py", line 3670, in edit_text
    return EditMessageText(
  File "C:\Users\комп\AppData\Local\Programs\Python\Python310\lib\site-packages\pydantic\main.py", line 214, in __init__
    validated_self = self.__pydantic_validator__.validate_python(data, self_instance=self)
pydantic_core._pydantic_core.ValidationError: 1 validation error for EditMessageText
reply_markup
  Input should be a valid dictionary or instance of InlineKeyboardMarkup [type=model_type, input_value=ReplyKeyboardMarkup(keybo...er=None, selective=None), input_type=ReplyKeyboardMarkup]
    For further information visit https://errors.pydantic.dev/2.10/v/model_type
2025-02-06 11:49:53,968 - INFO - Update id=619412439 is not handled. Duration 61 ms by bot id=7735807460
2025-02-06 11:49:53,968 - ERROR - Cause exception while process update id=619412439 by bot id=7735807460
ValidationError: 1 validation error for EditMessageText
reply_markup
  Input should be a valid dictionary or instance of InlineKeyboardMarkup [type=model_type, input_value=ReplyKeyboardMarkup(keybo...er=None, selective=None), input_type=ReplyKeyboardMarkup]
    For further information visit https://errors.pydantic.dev/2.10/v/model_type
Traceback (most recent call last):
  File "C:\Users\комп\AppData\Local\Programs\Python\Python310\lib\site-packages\aiogram\dispatcher\dispatcher.py", line 309, in _process_update
    response = await self.feed_update(bot, update, **kwargs)
  File "C:\Users\комп\AppData\Local\Programs\Python\Python310\lib\site-packages\aiogram\dispatcher\dispatcher.py", line 158, in feed_update
    response = await self.update.wrap_outer_middleware(
  File "C:\Users\комп\AppData\Local\Programs\Python\Python310\lib\site-packages\aiogram\dispatcher\middlewares\error.py", line 25, in __call__
    return await handler(event, data)
  File "C:\Users\комп\AppData\Local\Programs\Python\Python310\lib\site-packages\aiogram\dispatcher\middlewares\user_context.py", line 56, in __call__
    return await handler(event, data)
  File "C:\Users\комп\AppData\Local\Programs\Python\Python310\lib\site-packages\aiogram\fsm\middleware.py", line 42, in __call__
    return await handler(event, data)
  File "C:\Users\комп\AppData\Local\Programs\Python\Python310\lib\site-packages\aiogram\dispatcher\event\telegram.py", line 121, in trigger
    return await wrapped_inner(event, kwargs)
  File "C:\Users\комп\AppData\Local\Programs\Python\Python310\lib\site-packages\aiogram\dispatcher\event\handler.py", line 43, in call
    return await wrapped()
  File "C:\Users\комп\AppData\Local\Programs\Python\Python310\lib\site-packages\aiogram\dispatcher\dispatcher.py", line 276, in _listen_update
    return await self.propagate_event(update_type=update_type, event=event, **kwargs)
  File "C:\Users\комп\AppData\Local\Programs\Python\Python310\lib\site-packages\aiogram\dispatcher\router.py", line 146, in propagate_event
    return await observer.wrap_outer_middleware(_wrapped, event=event, data=kwargs)
  File "C:\Users\комп\AppData\Local\Programs\Python\Python310\lib\site-packages\aiogram\dispatcher\router.py", line 141, in _wrapped
    return await self._propagate_event(
  File "C:\Users\комп\AppData\Local\Programs\Python\Python310\lib\site-packages\aiogram\dispatcher\router.py", line 166, in _propagate_event
    response = await observer.trigger(event, **kwargs)
  File "C:\Users\комп\AppData\Local\Programs\Python\Python310\lib\site-packages\aiogram\dispatcher\event\telegram.py", line 121, in trigger
    return await wrapped_inner(event, kwargs)
  File "C:\Users\комп\AppData\Local\Programs\Python\Python310\lib\site-packages\aiogram\dispatcher\event\handler.py", line 43, in call
    return await wrapped()
  File "c:\Users\комп\Desktop\Gamma_m_Project\Gamma_M_infoBot\main.py", line 148, in back_to_workshop
    await call.message.edit_text('Выберите цех:', reply_markup=start_keyboard)
  File "C:\Users\комп\AppData\Local\Programs\Python\Python310\lib\site-packages\aiogram\types\message.py", line 3670, in edit_text
    return EditMessageText(
  File "C:\Users\комп\AppData\Local\Programs\Python\Python310\lib\site-packages\pydantic\main.py", line 214, in __init__
    validated_self = self.__pydantic_validator__.validate_python(data, self_instance=self)
pydantic_core._pydantic_core.ValidationError: 1 validation error for EditMessageText
reply_markup
  Input should be a valid dictionary or instance of InlineKeyboardMarkup [type=model_type, input_value=ReplyKeyboardMarkup(keybo...er=None, selective=None), input_type=ReplyKeyboardMarkup]
    For further information visit https://errors.pydantic.dev/2.10/v/model_type
2025-02-06 11:49:54,386 - INFO - Update id=619412440 is not handled. Duration 62 ms by bot id=7735807460
2025-02-06 11:49:54,387 - ERROR - Cause exception while process update id=619412440 by bot id=7735807460
ValidationError: 1 validation error for EditMessageText
reply_markup
  Input should be a valid dictionary or instance of InlineKeyboardMarkup [type=model_type, input_value=ReplyKeyboardMarkup(keybo...er=None, selective=None), input_type=ReplyKeyboardMarkup]
    For further information visit https://errors.pydantic.dev/2.10/v/model_type
Traceback (most recent call last):
  File "C:\Users\комп\AppData\Local\Programs\Python\Python310\lib\site-packages\aiogram\dispatcher\dispatcher.py", line 309, in _process_update
    response = await self.feed_update(bot, update, **kwargs)
  File "C:\Users\комп\AppData\Local\Programs\Python\Python310\lib\site-packages\aiogram\dispatcher\dispatcher.py", line 158, in feed_update
    response = await self.update.wrap_outer_middleware(
  File "C:\Users\комп\AppData\Local\Programs\Python\Python310\lib\site-packages\aiogram\dispatcher\middlewares\error.py", line 25, in __call__
    return await handler(event, data)
  File "C:\Users\комп\AppData\Local\Programs\Python\Python310\lib\site-packages\aiogram\dispatcher\middlewares\user_context.py", line 56, in __call__
    return await handler(event, data)
  File "C:\Users\комп\AppData\Local\Programs\Python\Python310\lib\site-packages\aiogram\fsm\middleware.py", line 42, in __call__
    return await handler(event, data)
  File "C:\Users\комп\AppData\Local\Programs\Python\Python310\lib\site-packages\aiogram\dispatcher\event\telegram.py", line 121, in trigger
    return await wrapped_inner(event, kwargs)
  File "C:\Users\комп\AppData\Local\Programs\Python\Python310\lib\site-packages\aiogram\dispatcher\event\handler.py", line 43, in call
    return await wrapped()
  File "C:\Users\комп\AppData\Local\Programs\Python\Python310\lib\site-packages\aiogram\dispatcher\dispatcher.py", line 276, in _listen_update
    return await self.propagate_event(update_type=update_type, event=event, **kwargs)
  File "C:\Users\комп\AppData\Local\Programs\Python\Python310\lib\site-packages\aiogram\dispatcher\router.py", line 146, in propagate_event
    return await observer.wrap_outer_middleware(_wrapped, event=event, data=kwargs)
  File "C:\Users\комп\AppData\Local\Programs\Python\Python310\lib\site-packages\aiogram\dispatcher\router.py", line 141, in _wrapped
    return await self._propagate_event(
  File "C:\Users\комп\AppData\Local\Programs\Python\Python310\lib\site-packages\aiogram\dispatcher\router.py", line 166, in _propagate_event
    response = await observer.trigger(event, **kwargs)
  File "C:\Users\комп\AppData\Local\Programs\Python\Python310\lib\site-packages\aiogram\dispatcher\event\telegram.py", line 121, in trigger
    return await wrapped_inner(event, kwargs)
  File "C:\Users\комп\AppData\Local\Programs\Python\Python310\lib\site-packages\aiogram\dispatcher\event\handler.py", line 43, in call
    return await wrapped()
  File "c:\Users\комп\Desktop\Gamma_m_Project\Gamma_M_infoBot\main.py", line 148, in back_to_workshop
    await call.message.edit_text('Выберите цех:', reply_markup=start_keyboard)
  File "C:\Users\комп\AppData\Local\Programs\Python\Python310\lib\site-packages\aiogram\types\message.py", line 3670, in edit_text
    return EditMessageText(
  File "C:\Users\комп\AppData\Local\Programs\Python\Python310\lib\site-packages\pydantic\main.py", line 214, in __init__
    validated_self = self.__pydantic_validator__.validate_python(data, self_instance=self)
pydantic_core._pydantic_core.ValidationError: 1 validation error for EditMessageText
reply_markup
  Input should be a valid dictionary or instance of InlineKeyboardMarkup [type=model_type, input_value=ReplyKeyboardMarkup(keybo...er=None, selective=None), input_type=ReplyKeyboardMarkup]
    For further information visit https://errors.pydantic.dev/2.10/v/model_type
2025-02-06 11:49:54,823 - INFO - Update id=619412441 is not handled. Duration 62 ms by bot id=7735807460
2025-02-06 11:49:54,823 - ERROR - Cause exception while process update id=619412441 by bot id=7735807460
ValidationError: 1 validation error for EditMessageText
reply_markup
  Input should be a valid dictionary or instance of InlineKeyboardMarkup [type=model_type, input_value=ReplyKeyboardMarkup(keybo...er=None, selective=None), input_type=ReplyKeyboardMarkup]
    For further information visit https://errors.pydantic.dev/2.10/v/model_type
Traceback (most recent call last):
  File "C:\Users\комп\AppData\Local\Programs\Python\Python310\lib\site-packages\aiogram\dispatcher\dispatcher.py", line 309, in _process_update
    response = await self.feed_update(bot, update, **kwargs)
  File "C:\Users\комп\AppData\Local\Programs\Python\Python310\lib\site-packages\aiogram\dispatcher\dispatcher.py", line 158, in feed_update
    response = await self.update.wrap_outer_middleware(
  File "C:\Users\комп\AppData\Local\Programs\Python\Python310\lib\site-packages\aiogram\dispatcher\middlewares\error.py", line 25, in __call__
    return await handler(event, data)
  File "C:\Users\комп\AppData\Local\Programs\Python\Python310\lib\site-packages\aiogram\dispatcher\middlewares\user_context.py", line 56, in __call__
    return await handler(event, data)
  File "C:\Users\комп\AppData\Local\Programs\Python\Python310\lib\site-packages\aiogram\fsm\middleware.py", line 42, in __call__
    return await handler(event, data)
  File "C:\Users\комп\AppData\Local\Programs\Python\Python310\lib\site-packages\aiogram\dispatcher\event\telegram.py", line 121, in trigger
    return await wrapped_inner(event, kwargs)
  File "C:\Users\комп\AppData\Local\Programs\Python\Python310\lib\site-packages\aiogram\dispatcher\event\handler.py", line 43, in call
    return await wrapped()
  File "C:\Users\комп\AppData\Local\Programs\Python\Python310\lib\site-packages\aiogram\dispatcher\dispatcher.py", line 276, in _listen_update
    return await self.propagate_event(update_type=update_type, event=event, **kwargs)
  File "C:\Users\комп\AppData\Local\Programs\Python\Python310\lib\site-packages\aiogram\dispatcher\router.py", line 146, in propagate_event
    return await observer.wrap_outer_middleware(_wrapped, event=event, data=kwargs)
  File "C:\Users\комп\AppData\Local\Programs\Python\Python310\lib\site-packages\aiogram\dispatcher\router.py", line 141, in _wrapped
    return await self._propagate_event(
  File "C:\Users\комп\AppData\Local\Programs\Python\Python310\lib\site-packages\aiogram\dispatcher\router.py", line 166, in _propagate_event
    response = await observer.trigger(event, **kwargs)
  File "C:\Users\комп\AppData\Local\Programs\Python\Python310\lib\site-packages\aiogram\dispatcher\event\telegram.py", line 121, in trigger
    return await wrapped_inner(event, kwargs)
  File "C:\Users\комп\AppData\Local\Programs\Python\Python310\lib\site-packages\aiogram\dispatcher\event\handler.py", line 43, in call
    return await wrapped()
  File "c:\Users\комп\Desktop\Gamma_m_Project\Gamma_M_infoBot\main.py", line 148, in back_to_workshop
    await call.message.edit_text('Выберите цех:', reply_markup=start_keyboard)
  File "C:\Users\комп\AppData\Local\Programs\Python\Python310\lib\site-packages\aiogram\types\message.py", line 3670, in edit_text
    return EditMessageText(
  File "C:\Users\комп\AppData\Local\Programs\Python\Python310\lib\site-packages\pydantic\main.py", line 214, in __init__
    validated_self = self.__pydantic_validator__.validate_python(data, self_instance=self)
pydantic_core._pydantic_core.ValidationError: 1 validation error for EditMessageText
reply_markup
  Input should be a valid dictionary or instance of InlineKeyboardMarkup [type=model_type, input_value=ReplyKeyboardMarkup(keybo...er=None, selective=None), input_type=ReplyKeyboardMarkup]
    For further information visit https://errors.pydantic.dev/2.10/v/model_type
2025-02-06 11:49:55,233 - INFO - Update id=619412442 is not handled. Duration 63 ms by bot id=7735807460
2025-02-06 11:49:55,233 - ERROR - Cause exception while process update id=619412442 by bot id=7735807460
ValidationError: 1 validation error for EditMessageText
reply_markup
  Input should be a valid dictionary or instance of InlineKeyboardMarkup [type=model_type, input_value=ReplyKeyboardMarkup(keybo...er=None, selective=None), input_type=ReplyKeyboardMarkup]
    For further information visit https://errors.pydantic.dev/2.10/v/model_type
Traceback (most recent call last):
  File "C:\Users\комп\AppData\Local\Programs\Python\Python310\lib\site-packages\aiogram\dispatcher\dispatcher.py", line 309, in _process_update
    response = await self.feed_update(bot, update, **kwargs)
  File "C:\Users\комп\AppData\Local\Programs\Python\Python310\lib\site-packages\aiogram\dispatcher\dispatcher.py", line 158, in feed_update
    response = await self.update.wrap_outer_middleware(
  File "C:\Users\комп\AppData\Local\Programs\Python\Python310\lib\site-packages\aiogram\dispatcher\middlewares\error.py", line 25, in __call__
    return await handler(event, data)
  File "C:\Users\комп\AppData\Local\Programs\Python\Python310\lib\site-packages\aiogram\dispatcher\middlewares\user_context.py", line 56, in __call__
    return await handler(event, data)
  File "C:\Users\комп\AppData\Local\Programs\Python\Python310\lib\site-packages\aiogram\fsm\middleware.py", line 42, in __call__
    return await handler(event, data)
  File "C:\Users\комп\AppData\Local\Programs\Python\Python310\lib\site-packages\aiogram\dispatcher\event\telegram.py", line 121, in trigger
    return await wrapped_inner(event, kwargs)
  File "C:\Users\комп\AppData\Local\Programs\Python\Python310\lib\site-packages\aiogram\dispatcher\event\handler.py", line 43, in call
    return await wrapped()
  File "C:\Users\комп\AppData\Local\Programs\Python\Python310\lib\site-packages\aiogram\dispatcher\dispatcher.py", line 276, in _listen_update
    return await self.propagate_event(update_type=update_type, event=event, **kwargs)
  File "C:\Users\комп\AppData\Local\Programs\Python\Python310\lib\site-packages\aiogram\dispatcher\router.py", line 146, in propagate_event
    return await observer.wrap_outer_middleware(_wrapped, event=event, data=kwargs)
  File "C:\Users\комп\AppData\Local\Programs\Python\Python310\lib\site-packages\aiogram\dispatcher\router.py", line 141, in _wrapped
    return await self._propagate_event(
  File "C:\Users\комп\AppData\Local\Programs\Python\Python310\lib\site-packages\aiogram\dispatcher\router.py", line 166, in _propagate_event
    response = await observer.trigger(event, **kwargs)
  File "C:\Users\комп\AppData\Local\Programs\Python\Python310\lib\site-packages\aiogram\dispatcher\event\telegram.py", line 121, in trigger
    return await wrapped_inner(event, kwargs)
  File "C:\Users\комп\AppData\Local\Programs\Python\Python310\lib\site-packages\aiogram\dispatcher\event\handler.py", line 43, in call
    return await wrapped()
  File "c:\Users\комп\Desktop\Gamma_m_Project\Gamma_M_infoBot\main.py", line 148, in back_to_workshop
    await call.message.edit_text('Выберите цех:', reply_markup=start_keyboard)
  File "C:\Users\комп\AppData\Local\Programs\Python\Python310\lib\site-packages\aiogram\types\message.py", line 3670, in edit_text
    return EditMessageText(
  File "C:\Users\комп\AppData\Local\Programs\Python\Python310\lib\site-packages\pydantic\main.py", line 214, in __init__
    validated_self = self.__pydantic_validator__.validate_python(data, self_instance=self)
pydantic_core._pydantic_core.ValidationError: 1 validation error for EditMessageText
reply_markup
  Input should be a valid dictionary or instance of InlineKeyboardMarkup [type=model_type, input_value=ReplyKeyboardMarkup(keybo...er=None, selective=None), input_type=ReplyKeyboardMarkup]
    For further information visit https://errors.pydantic.dev/2.10/v/model_type
2025-02-06 11:49:58,147 - ERROR - В файле workshop 2.xlsx отсутствует столбец 'Машина'.
2025-02-06 11:49:58,147 - INFO - Update id=619412443 is handled. Duration 93 ms by bot id=7735807460
2025-02-06 11:49:58,963 - INFO - Update id=619412444 is not handled. Duration 93 ms by bot id=7735807460
2025-02-06 11:49:58,963 - ERROR - Cause exception while process update id=619412444 by bot id=7735807460
ValidationError: 1 validation error for EditMessageText
reply_markup
  Input should be a valid dictionary or instance of InlineKeyboardMarkup [type=model_type, input_value=ReplyKeyboardMarkup(keybo...er=None, selective=None), input_type=ReplyKeyboardMarkup]
    For further information visit https://errors.pydantic.dev/2.10/v/model_type
Traceback (most recent call last):
  File "C:\Users\комп\AppData\Local\Programs\Python\Python310\lib\site-packages\aiogram\dispatcher\dispatcher.py", line 309, in _process_update
    response = await self.feed_update(bot, update, **kwargs)
  File "C:\Users\комп\AppData\Local\Programs\Python\Python310\lib\site-packages\aiogram\dispatcher\dispatcher.py", line 158, in feed_update
    response = await self.update.wrap_outer_middleware(
  File "C:\Users\комп\AppData\Local\Programs\Python\Python310\lib\site-packages\aiogram\dispatcher\middlewares\error.py", line 25, in __call__
    return await handler(event, data)
  File "C:\Users\комп\AppData\Local\Programs\Python\Python310\lib\site-packages\aiogram\dispatcher\middlewares\user_context.py", line 56, in __call__
    return await handler(event, data)
  File "C:\Users\комп\AppData\Local\Programs\Python\Python310\lib\site-packages\aiogram\fsm\middleware.py", line 42, in __call__
    return await handler(event, data)
  File "C:\Users\комп\AppData\Local\Programs\Python\Python310\lib\site-packages\aiogram\dispatcher\event\telegram.py", line 121, in trigger
    return await wrapped_inner(event, kwargs)
  File "C:\Users\комп\AppData\Local\Programs\Python\Python310\lib\site-packages\aiogram\dispatcher\event\handler.py", line 43, in call
    return await wrapped()
  File "C:\Users\комп\AppData\Local\Programs\Python\Python310\lib\site-packages\aiogram\dispatcher\dispatcher.py", line 276, in _listen_update
    return await self.propagate_event(update_type=update_type, event=event, **kwargs)
  File "C:\Users\комп\AppData\Local\Programs\Python\Python310\lib\site-packages\aiogram\dispatcher\router.py", line 146, in propagate_event
    return await observer.wrap_outer_middleware(_wrapped, event=event, data=kwargs)
  File "C:\Users\комп\AppData\Local\Programs\Python\Python310\lib\site-packages\aiogram\dispatcher\router.py", line 141, in _wrapped
    return await self._propagate_event(
  File "C:\Users\комп\AppData\Local\Programs\Python\Python310\lib\site-packages\aiogram\dispatcher\router.py", line 166, in _propagate_event
    response = await observer.trigger(event, **kwargs)
  File "C:\Users\комп\AppData\Local\Programs\Python\Python310\lib\site-packages\aiogram\dispatcher\event\telegram.py", line 121, in trigger
    return await wrapped_inner(event, kwargs)
  File "C:\Users\комп\AppData\Local\Programs\Python\Python310\lib\site-packages\aiogram\dispatcher\event\handler.py", line 43, in call
    return await wrapped()
  File "c:\Users\комп\Desktop\Gamma_m_Project\Gamma_M_infoBot\main.py", line 148, in back_to_workshop
    await call.message.edit_text('Выберите цех:', reply_markup=start_keyboard)
  File "C:\Users\комп\AppData\Local\Programs\Python\Python310\lib\site-packages\aiogram\types\message.py", line 3670, in edit_text
    return EditMessageText(
  File "C:\Users\комп\AppData\Local\Programs\Python\Python310\lib\site-packages\pydantic\main.py", line 214, in __init__
    validated_self = self.__pydantic_validator__.validate_python(data, self_instance=self)
pydantic_core._pydantic_core.ValidationError: 1 validation error for EditMessageText
reply_markup
  Input should be a valid dictionary or instance of InlineKeyboardMarkup [type=model_type, input_value=ReplyKeyboardMarkup(keybo...er=None, selective=None), input_type=ReplyKeyboardMarkup]
    For further information visit https://errors.pydantic.dev/2.10/v/model_type
2025-02-06 11:49:59,255 - INFO - Update id=619412445 is not handled. Duration 61 ms by bot id=7735807460
2025-02-06 11:49:59,256 - ERROR - Cause exception while process update id=619412445 by bot id=7735807460
ValidationError: 1 validation error for EditMessageText
reply_markup
  Input should be a valid dictionary or instance of InlineKeyboardMarkup [type=model_type, input_value=ReplyKeyboardMarkup(keybo...er=None, selective=None), input_type=ReplyKeyboardMarkup]
    For further information visit https://errors.pydantic.dev/2.10/v/model_type
Traceback (most recent call last):
  File "C:\Users\комп\AppData\Local\Programs\Python\Python310\lib\site-packages\aiogram\dispatcher\dispatcher.py", line 309, in _process_update
    response = await self.feed_update(bot, update, **kwargs)
  File "C:\Users\комп\AppData\Local\Programs\Python\Python310\lib\site-packages\aiogram\dispatcher\dispatcher.py", line 158, in feed_update
    response = await self.update.wrap_outer_middleware(
  File "C:\Users\комп\AppData\Local\Programs\Python\Python310\lib\site-packages\aiogram\dispatcher\middlewares\error.py", line 25, in __call__
    return await handler(event, data)
  File "C:\Users\комп\AppData\Local\Programs\Python\Python310\lib\site-packages\aiogram\dispatcher\middlewares\user_context.py", line 56, in __call__
    return await handler(event, data)
  File "C:\Users\комп\AppData\Local\Programs\Python\Python310\lib\site-packages\aiogram\fsm\middleware.py", line 42, in __call__
    return await handler(event, data)
  File "C:\Users\комп\AppData\Local\Programs\Python\Python310\lib\site-packages\aiogram\dispatcher\event\telegram.py", line 121, in trigger
    return await wrapped_inner(event, kwargs)
  File "C:\Users\комп\AppData\Local\Programs\Python\Python310\lib\site-packages\aiogram\dispatcher\event\handler.py", line 43, in call
    return await wrapped()
  File "C:\Users\комп\AppData\Local\Programs\Python\Python310\lib\site-packages\aiogram\dispatcher\dispatcher.py", line 276, in _listen_update
    return await self.propagate_event(update_type=update_type, event=event, **kwargs)
  File "C:\Users\комп\AppData\Local\Programs\Python\Python310\lib\site-packages\aiogram\dispatcher\router.py", line 146, in propagate_event
    return await observer.wrap_outer_middleware(_wrapped, event=event, data=kwargs)
  File "C:\Users\комп\AppData\Local\Programs\Python\Python310\lib\site-packages\aiogram\dispatcher\router.py", line 141, in _wrapped
    return await self._propagate_event(
  File "C:\Users\комп\AppData\Local\Programs\Python\Python310\lib\site-packages\aiogram\dispatcher\router.py", line 166, in _propagate_event
    response = await observer.trigger(event, **kwargs)
  File "C:\Users\комп\AppData\Local\Programs\Python\Python310\lib\site-packages\aiogram\dispatcher\event\telegram.py", line 121, in trigger
    return await wrapped_inner(event, kwargs)
  File "C:\Users\комп\AppData\Local\Programs\Python\Python310\lib\site-packages\aiogram\dispatcher\event\handler.py", line 43, in call
    return await wrapped()
  File "c:\Users\комп\Desktop\Gamma_m_Project\Gamma_M_infoBot\main.py", line 148, in back_to_workshop
    await call.message.edit_text('Выберите цех:', reply_markup=start_keyboard)
  File "C:\Users\комп\AppData\Local\Programs\Python\Python310\lib\site-packages\aiogram\types\message.py", line 3670, in edit_text
    return EditMessageText(
  File "C:\Users\комп\AppData\Local\Programs\Python\Python310\lib\site-packages\pydantic\main.py", line 214, in __init__
    validated_self = self.__pydantic_validator__.validate_python(data, self_instance=self)
pydantic_core._pydantic_core.ValidationError: 1 validation error for EditMessageText
reply_markup
  Input should be a valid dictionary or instance of InlineKeyboardMarkup [type=model_type, input_value=ReplyKeyboardMarkup(keybo...er=None, selective=None), input_type=ReplyKeyboardMarkup]
    For further information visit https://errors.pydantic.dev/2.10/v/model_type
2025-02-06 11:49:59,754 - INFO - Update id=619412446 is not handled. Duration 61 ms by bot id=7735807460
2025-02-06 11:49:59,754 - ERROR - Cause exception while process update id=619412446 by bot id=7735807460
ValidationError: 1 validation error for EditMessageText
reply_markup
  Input should be a valid dictionary or instance of InlineKeyboardMarkup [type=model_type, input_value=ReplyKeyboardMarkup(keybo...er=None, selective=None), input_type=ReplyKeyboardMarkup]
    For further information visit https://errors.pydantic.dev/2.10/v/model_type
Traceback (most recent call last):
  File "C:\Users\комп\AppData\Local\Programs\Python\Python310\lib\site-packages\aiogram\dispatcher\dispatcher.py", line 309, in _process_update
    response = await self.feed_update(bot, update, **kwargs)
  File "C:\Users\комп\AppData\Local\Programs\Python\Python310\lib\site-packages\aiogram\dispatcher\dispatcher.py", line 158, in feed_update
    response = await self.update.wrap_outer_middleware(
  File "C:\Users\комп\AppData\Local\Programs\Python\Python310\lib\site-packages\aiogram\dispatcher\middlewares\error.py", line 25, in __call__
    return await handler(event, data)
  File "C:\Users\комп\AppData\Local\Programs\Python\Python310\lib\site-packages\aiogram\dispatcher\middlewares\user_context.py", line 56, in __call__
    return await handler(event, data)
  File "C:\Users\комп\AppData\Local\Programs\Python\Python310\lib\site-packages\aiogram\fsm\middleware.py", line 42, in __call__
    return await handler(event, data)
  File "C:\Users\комп\AppData\Local\Programs\Python\Python310\lib\site-packages\aiogram\dispatcher\event\telegram.py", line 121, in trigger
    return await wrapped_inner(event, kwargs)
  File "C:\Users\комп\AppData\Local\Programs\Python\Python310\lib\site-packages\aiogram\dispatcher\event\handler.py", line 43, in call
    return await wrapped()
  File "C:\Users\комп\AppData\Local\Programs\Python\Python310\lib\site-packages\aiogram\dispatcher\dispatcher.py", line 276, in _listen_update
    return await self.propagate_event(update_type=update_type, event=event, **kwargs)
  File "C:\Users\комп\AppData\Local\Programs\Python\Python310\lib\site-packages\aiogram\dispatcher\router.py", line 146, in propagate_event
    return await observer.wrap_outer_middleware(_wrapped, event=event, data=kwargs)
  File "C:\Users\комп\AppData\Local\Programs\Python\Python310\lib\site-packages\aiogram\dispatcher\router.py", line 141, in _wrapped
    return await self._propagate_event(
  File "C:\Users\комп\AppData\Local\Programs\Python\Python310\lib\site-packages\aiogram\dispatcher\router.py", line 166, in _propagate_event
    response = await observer.trigger(event, **kwargs)
  File "C:\Users\комп\AppData\Local\Programs\Python\Python310\lib\site-packages\aiogram\dispatcher\event\telegram.py", line 121, in trigger
    return await wrapped_inner(event, kwargs)
  File "C:\Users\комп\AppData\Local\Programs\Python\Python310\lib\site-packages\aiogram\dispatcher\event\handler.py", line 43, in call
    return await wrapped()
  File "c:\Users\комп\Desktop\Gamma_m_Project\Gamma_M_infoBot\main.py", line 148, in back_to_workshop
    await call.message.edit_text('Выберите цех:', reply_markup=start_keyboard)
  File "C:\Users\комп\AppData\Local\Programs\Python\Python310\lib\site-packages\aiogram\types\message.py", line 3670, in edit_text
    return EditMessageText(
  File "C:\Users\комп\AppData\Local\Programs\Python\Python310\lib\site-packages\pydantic\main.py", line 214, in __init__
    validated_self = self.__pydantic_validator__.validate_python(data, self_instance=self)
pydantic_core._pydantic_core.ValidationError: 1 validation error for EditMessageText
reply_markup
  Input should be a valid dictionary or instance of InlineKeyboardMarkup [type=model_type, input_value=ReplyKeyboardMarkup(keybo...er=None, selective=None), input_type=ReplyKeyboardMarkup]
    For further information visit https://errors.pydantic.dev/2.10/v/model_type
2025-02-06 11:49:59,820 - INFO - Update id=619412447 is not handled. Duration 78 ms by bot id=7735807460
2025-02-06 11:49:59,820 - ERROR - Cause exception while process update id=619412447 by bot id=7735807460
ValidationError: 1 validation error for EditMessageText
reply_markup
  Input should be a valid dictionary or instance of InlineKeyboardMarkup [type=model_type, input_value=ReplyKeyboardMarkup(keybo...er=None, selective=None), input_type=ReplyKeyboardMarkup]
    For further information visit https://errors.pydantic.dev/2.10/v/model_type
Traceback (most recent call last):
  File "C:\Users\комп\AppData\Local\Programs\Python\Python310\lib\site-packages\aiogram\dispatcher\dispatcher.py", line 309, in _process_update
    response = await self.feed_update(bot, update, **kwargs)
  File "C:\Users\комп\AppData\Local\Programs\Python\Python310\lib\site-packages\aiogram\dispatcher\dispatcher.py", line 158, in feed_update
    response = await self.update.wrap_outer_middleware(
  File "C:\Users\комп\AppData\Local\Programs\Python\Python310\lib\site-packages\aiogram\dispatcher\middlewares\error.py", line 25, in __call__
    return await handler(event, data)
  File "C:\Users\комп\AppData\Local\Programs\Python\Python310\lib\site-packages\aiogram\dispatcher\middlewares\user_context.py", line 56, in __call__
    return await handler(event, data)
  File "C:\Users\комп\AppData\Local\Programs\Python\Python310\lib\site-packages\aiogram\fsm\middleware.py", line 42, in __call__
    return await handler(event, data)
  File "C:\Users\комп\AppData\Local\Programs\Python\Python310\lib\site-packages\aiogram\dispatcher\event\telegram.py", line 121, in trigger
    return await wrapped_inner(event, kwargs)
  File "C:\Users\комп\AppData\Local\Programs\Python\Python310\lib\site-packages\aiogram\dispatcher\event\handler.py", line 43, in call
    return await wrapped()
  File "C:\Users\комп\AppData\Local\Programs\Python\Python310\lib\site-packages\aiogram\dispatcher\dispatcher.py", line 276, in _listen_update
    return await self.propagate_event(update_type=update_type, event=event, **kwargs)
  File "C:\Users\комп\AppData\Local\Programs\Python\Python310\lib\site-packages\aiogram\dispatcher\router.py", line 146, in propagate_event
    return await observer.wrap_outer_middleware(_wrapped, event=event, data=kwargs)
  File "C:\Users\комп\AppData\Local\Programs\Python\Python310\lib\site-packages\aiogram\dispatcher\router.py", line 141, in _wrapped
    return await self._propagate_event(
  File "C:\Users\комп\AppData\Local\Programs\Python\Python310\lib\site-packages\aiogram\dispatcher\router.py", line 166, in _propagate_event
    response = await observer.trigger(event, **kwargs)
  File "C:\Users\комп\AppData\Local\Programs\Python\Python310\lib\site-packages\aiogram\dispatcher\event\telegram.py", line 121, in trigger
    return await wrapped_inner(event, kwargs)
  File "C:\Users\комп\AppData\Local\Programs\Python\Python310\lib\site-packages\aiogram\dispatcher\event\handler.py", line 43, in call
    return await wrapped()
  File "c:\Users\комп\Desktop\Gamma_m_Project\Gamma_M_infoBot\main.py", line 148, in back_to_workshop
    await call.message.edit_text('Выберите цех:', reply_markup=start_keyboard)
  File "C:\Users\комп\AppData\Local\Programs\Python\Python310\lib\site-packages\aiogram\types\message.py", line 3670, in edit_text
    return EditMessageText(
  File "C:\Users\комп\AppData\Local\Programs\Python\Python310\lib\site-packages\pydantic\main.py", line 214, in __init__
    validated_self = self.__pydantic_validator__.validate_python(data, self_instance=self)
pydantic_core._pydantic_core.ValidationError: 1 validation error for EditMessageText
reply_markup
  Input should be a valid dictionary or instance of InlineKeyboardMarkup [type=model_type, input_value=ReplyKeyboardMarkup(keybo...er=None, selective=None), input_type=ReplyKeyboardMarkup]
    For further information visit https://errors.pydantic.dev/2.10/v/model_type
2025-02-06 11:50:27,818 - ERROR - Ошибка при чтении файла: [Errno 2] No such file or directory: 'Machine_info.txt'
2025-02-06 11:50:27,818 - INFO - Update id=619412448 is handled. Duration 0 ms by bot id=7735807460
2025-02-06 11:50:28,415 - ERROR - Ошибка при чтении файла: [Errno 2] No such file or directory: 'Machine_info.txt'
2025-02-06 11:50:28,416 - INFO - Update id=619412449 is handled. Duration 0 ms by bot id=7735807460
2025-02-06 11:50:28,860 - ERROR - Ошибка при чтении файла: [Errno 2] No such file or directory: 'Machine_info.txt'
2025-02-06 11:50:28,860 - INFO - Update id=619412450 is handled. Duration 0 ms by bot id=7735807460
2025-02-06 11:50:29,167 - ERROR - Ошибка при чтении файла: [Errno 2] No such file or directory: 'Machine_info.txt'
2025-02-06 11:50:29,167 - INFO - Update id=619412451 is handled. Duration 0 ms by bot id=7735807460
2025-02-06 11:50:29,821 - INFO - Update id=619412452 is not handled. Duration 93 ms by bot id=7735807460
2025-02-06 11:50:29,821 - ERROR - Cause exception while process update id=619412452 by bot id=7735807460
ValidationError: 1 validation error for EditMessageText
reply_markup
  Input should be a valid dictionary or instance of InlineKeyboardMarkup [type=model_type, input_value=ReplyKeyboardMarkup(keybo...er=None, selective=None), input_type=ReplyKeyboardMarkup]
    For further information visit https://errors.pydantic.dev/2.10/v/model_type
Traceback (most recent call last):
  File "C:\Users\комп\AppData\Local\Programs\Python\Python310\lib\site-packages\aiogram\dispatcher\dispatcher.py", line 309, in _process_update
    response = await self.feed_update(bot, update, **kwargs)
  File "C:\Users\комп\AppData\Local\Programs\Python\Python310\lib\site-packages\aiogram\dispatcher\dispatcher.py", line 158, in feed_update
    response = await self.update.wrap_outer_middleware(
  File "C:\Users\комп\AppData\Local\Programs\Python\Python310\lib\site-packages\aiogram\dispatcher\middlewares\error.py", line 25, in __call__
    return await handler(event, data)
  File "C:\Users\комп\AppData\Local\Programs\Python\Python310\lib\site-packages\aiogram\dispatcher\middlewares\user_context.py", line 56, in __call__
    return await handler(event, data)
  File "C:\Users\комп\AppData\Local\Programs\Python\Python310\lib\site-packages\aiogram\fsm\middleware.py", line 42, in __call__
    return await handler(event, data)
  File "C:\Users\комп\AppData\Local\Programs\Python\Python310\lib\site-packages\aiogram\dispatcher\event\telegram.py", line 121, in trigger
    return await wrapped_inner(event, kwargs)
  File "C:\Users\комп\AppData\Local\Programs\Python\Python310\lib\site-packages\aiogram\dispatcher\event\handler.py", line 43, in call
    return await wrapped()
  File "C:\Users\комп\AppData\Local\Programs\Python\Python310\lib\site-packages\aiogram\dispatcher\dispatcher.py", line 276, in _listen_update
    return await self.propagate_event(update_type=update_type, event=event, **kwargs)
  File "C:\Users\комп\AppData\Local\Programs\Python\Python310\lib\site-packages\aiogram\dispatcher\router.py", line 146, in propagate_event
    return await observer.wrap_outer_middleware(_wrapped, event=event, data=kwargs)
  File "C:\Users\комп\AppData\Local\Programs\Python\Python310\lib\site-packages\aiogram\dispatcher\router.py", line 141, in _wrapped
    return await self._propagate_event(
  File "C:\Users\комп\AppData\Local\Programs\Python\Python310\lib\site-packages\aiogram\dispatcher\router.py", line 166, in _propagate_event
    response = await observer.trigger(event, **kwargs)
  File "C:\Users\комп\AppData\Local\Programs\Python\Python310\lib\site-packages\aiogram\dispatcher\event\telegram.py", line 121, in trigger
    return await wrapped_inner(event, kwargs)
  File "C:\Users\комп\AppData\Local\Programs\Python\Python310\lib\site-packages\aiogram\dispatcher\event\handler.py", line 43, in call
    return await wrapped()
  File "c:\Users\комп\Desktop\Gamma_m_Project\Gamma_M_infoBot\main.py", line 148, in back_to_workshop
    await call.message.edit_text('Выберите цех:', reply_markup=start_keyboard)
  File "C:\Users\комп\AppData\Local\Programs\Python\Python310\lib\site-packages\aiogram\types\message.py", line 3670, in edit_text
    return EditMessageText(
  File "C:\Users\комп\AppData\Local\Programs\Python\Python310\lib\site-packages\pydantic\main.py", line 214, in __init__
    validated_self = self.__pydantic_validator__.validate_python(data, self_instance=self)
pydantic_core._pydantic_core.ValidationError: 1 validation error for EditMessageText
reply_markup
  Input should be a valid dictionary or instance of InlineKeyboardMarkup [type=model_type, input_value=ReplyKeyboardMarkup(keybo...er=None, selective=None), input_type=ReplyKeyboardMarkup]
    For further information visit https://errors.pydantic.dev/2.10/v/model_type
2025-02-06 11:50:33,151 - INFO - Update id=619412453 is not handled. Duration 156 ms by bot id=7735807460
2025-02-06 11:50:33,152 - ERROR - Cause exception while process update id=619412453 by bot id=7735807460
ValidationError: 1 validation error for EditMessageText
reply_markup
  Input should be a valid dictionary or instance of InlineKeyboardMarkup [type=model_type, input_value=ReplyKeyboardMarkup(keybo...er=None, selective=None), input_type=ReplyKeyboardMarkup]
    For further information visit https://errors.pydantic.dev/2.10/v/model_type
Traceback (most recent call last):
  File "C:\Users\комп\AppData\Local\Programs\Python\Python310\lib\site-packages\aiogram\dispatcher\dispatcher.py", line 309, in _process_update
    response = await self.feed_update(bot, update, **kwargs)
  File "C:\Users\комп\AppData\Local\Programs\Python\Python310\lib\site-packages\aiogram\dispatcher\dispatcher.py", line 158, in feed_update
    response = await self.update.wrap_outer_middleware(
  File "C:\Users\комп\AppData\Local\Programs\Python\Python310\lib\site-packages\aiogram\dispatcher\middlewares\error.py", line 25, in __call__
    return await handler(event, data)
  File "C:\Users\комп\AppData\Local\Programs\Python\Python310\lib\site-packages\aiogram\dispatcher\middlewares\user_context.py", line 56, in __call__
    return await handler(event, data)
  File "C:\Users\комп\AppData\Local\Programs\Python\Python310\lib\site-packages\aiogram\fsm\middleware.py", line 42, in __call__
    return await handler(event, data)
  File "C:\Users\комп\AppData\Local\Programs\Python\Python310\lib\site-packages\aiogram\dispatcher\event\telegram.py", line 121, in trigger
    return await wrapped_inner(event, kwargs)
  File "C:\Users\комп\AppData\Local\Programs\Python\Python310\lib\site-packages\aiogram\dispatcher\event\handler.py", line 43, in call
    return await wrapped()
  File "C:\Users\комп\AppData\Local\Programs\Python\Python310\lib\site-packages\aiogram\dispatcher\dispatcher.py", line 276, in _listen_update
    return await self.propagate_event(update_type=update_type, event=event, **kwargs)
  File "C:\Users\комп\AppData\Local\Programs\Python\Python310\lib\site-packages\aiogram\dispatcher\router.py", line 146, in propagate_event
    return await observer.wrap_outer_middleware(_wrapped, event=event, data=kwargs)
  File "C:\Users\комп\AppData\Local\Programs\Python\Python310\lib\site-packages\aiogram\dispatcher\router.py", line 141, in _wrapped
    return await self._propagate_event(
  File "C:\Users\комп\AppData\Local\Programs\Python\Python310\lib\site-packages\aiogram\dispatcher\router.py", line 166, in _propagate_event
    response = await observer.trigger(event, **kwargs)
  File "C:\Users\комп\AppData\Local\Programs\Python\Python310\lib\site-packages\aiogram\dispatcher\event\telegram.py", line 121, in trigger
    return await wrapped_inner(event, kwargs)
  File "C:\Users\комп\AppData\Local\Programs\Python\Python310\lib\site-packages\aiogram\dispatcher\event\handler.py", line 43, in call
    return await wrapped()
  File "c:\Users\комп\Desktop\Gamma_m_Project\Gamma_M_infoBot\main.py", line 148, in back_to_workshop
    await call.message.edit_text('Выберите цех:', reply_markup=start_keyboard)
  File "C:\Users\комп\AppData\Local\Programs\Python\Python310\lib\site-packages\aiogram\types\message.py", line 3670, in edit_text
    return EditMessageText(
  File "C:\Users\комп\AppData\Local\Programs\Python\Python310\lib\site-packages\pydantic\main.py", line 214, in __init__
    validated_self = self.__pydantic_validator__.validate_python(data, self_instance=self)
pydantic_core._pydantic_core.ValidationError: 1 validation error for EditMessageText
reply_markup
  Input should be a valid dictionary or instance of InlineKeyboardMarkup [type=model_type, input_value=ReplyKeyboardMarkup(keybo...er=None, selective=None), input_type=ReplyKeyboardMarkup]
    For further information visit https://errors.pydantic.dev/2.10/v/model_type
2025-02-06 11:50:33,611 - INFO - Update id=619412454 is not handled. Duration 171 ms by bot id=7735807460
2025-02-06 11:50:33,611 - ERROR - Cause exception while process update id=619412454 by bot id=7735807460
ValidationError: 1 validation error for EditMessageText
reply_markup
  Input should be a valid dictionary or instance of InlineKeyboardMarkup [type=model_type, input_value=ReplyKeyboardMarkup(keybo...er=None, selective=None), input_type=ReplyKeyboardMarkup]
    For further information visit https://errors.pydantic.dev/2.10/v/model_type
Traceback (most recent call last):
  File "C:\Users\комп\AppData\Local\Programs\Python\Python310\lib\site-packages\aiogram\dispatcher\dispatcher.py", line 309, in _process_update
    response = await self.feed_update(bot, update, **kwargs)
  File "C:\Users\комп\AppData\Local\Programs\Python\Python310\lib\site-packages\aiogram\dispatcher\dispatcher.py", line 158, in feed_update
    response = await self.update.wrap_outer_middleware(
  File "C:\Users\комп\AppData\Local\Programs\Python\Python310\lib\site-packages\aiogram\dispatcher\middlewares\error.py", line 25, in __call__
    return await handler(event, data)
  File "C:\Users\комп\AppData\Local\Programs\Python\Python310\lib\site-packages\aiogram\dispatcher\middlewares\user_context.py", line 56, in __call__
    return await handler(event, data)
  File "C:\Users\комп\AppData\Local\Programs\Python\Python310\lib\site-packages\aiogram\fsm\middleware.py", line 42, in __call__
    return await handler(event, data)
  File "C:\Users\комп\AppData\Local\Programs\Python\Python310\lib\site-packages\aiogram\dispatcher\event\telegram.py", line 121, in trigger
    return await wrapped_inner(event, kwargs)
  File "C:\Users\комп\AppData\Local\Programs\Python\Python310\lib\site-packages\aiogram\dispatcher\event\handler.py", line 43, in call
    return await wrapped()
  File "C:\Users\комп\AppData\Local\Programs\Python\Python310\lib\site-packages\aiogram\dispatcher\dispatcher.py", line 276, in _listen_update
    return await self.propagate_event(update_type=update_type, event=event, **kwargs)
  File "C:\Users\комп\AppData\Local\Programs\Python\Python310\lib\site-packages\aiogram\dispatcher\router.py", line 146, in propagate_event
    return await observer.wrap_outer_middleware(_wrapped, event=event, data=kwargs)
  File "C:\Users\комп\AppData\Local\Programs\Python\Python310\lib\site-packages\aiogram\dispatcher\router.py", line 141, in _wrapped
    return await self._propagate_event(
  File "C:\Users\комп\AppData\Local\Programs\Python\Python310\lib\site-packages\aiogram\dispatcher\router.py", line 166, in _propagate_event
    response = await observer.trigger(event, **kwargs)
  File "C:\Users\комп\AppData\Local\Programs\Python\Python310\lib\site-packages\aiogram\dispatcher\event\telegram.py", line 121, in trigger
    return await wrapped_inner(event, kwargs)
  File "C:\Users\комп\AppData\Local\Programs\Python\Python310\lib\site-packages\aiogram\dispatcher\event\handler.py", line 43, in call
    return await wrapped()
  File "c:\Users\комп\Desktop\Gamma_m_Project\Gamma_M_infoBot\main.py", line 148, in back_to_workshop
    await call.message.edit_text('Выберите цех:', reply_markup=start_keyboard)
  File "C:\Users\комп\AppData\Local\Programs\Python\Python310\lib\site-packages\aiogram\types\message.py", line 3670, in edit_text
    return EditMessageText(
  File "C:\Users\комп\AppData\Local\Programs\Python\Python310\lib\site-packages\pydantic\main.py", line 214, in __init__
    validated_self = self.__pydantic_validator__.validate_python(data, self_instance=self)
pydantic_core._pydantic_core.ValidationError: 1 validation error for EditMessageText
reply_markup
  Input should be a valid dictionary or instance of InlineKeyboardMarkup [type=model_type, input_value=ReplyKeyboardMarkup(keybo...er=None, selective=None), input_type=ReplyKeyboardMarkup]
    For further information visit https://errors.pydantic.dev/2.10/v/model_type
2025-02-06 11:50:33,823 - INFO - Update id=619412455 is not handled. Duration 156 ms by bot id=7735807460
2025-02-06 11:50:33,823 - ERROR - Cause exception while process update id=619412455 by bot id=7735807460
ValidationError: 1 validation error for EditMessageText
reply_markup
  Input should be a valid dictionary or instance of InlineKeyboardMarkup [type=model_type, input_value=ReplyKeyboardMarkup(keybo...er=None, selective=None), input_type=ReplyKeyboardMarkup]
    For further information visit https://errors.pydantic.dev/2.10/v/model_type
Traceback (most recent call last):
  File "C:\Users\комп\AppData\Local\Programs\Python\Python310\lib\site-packages\aiogram\dispatcher\dispatcher.py", line 309, in _process_update
    response = await self.feed_update(bot, update, **kwargs)
  File "C:\Users\комп\AppData\Local\Programs\Python\Python310\lib\site-packages\aiogram\dispatcher\dispatcher.py", line 158, in feed_update
    response = await self.update.wrap_outer_middleware(
  File "C:\Users\комп\AppData\Local\Programs\Python\Python310\lib\site-packages\aiogram\dispatcher\middlewares\error.py", line 25, in __call__
    return await handler(event, data)
  File "C:\Users\комп\AppData\Local\Programs\Python\Python310\lib\site-packages\aiogram\dispatcher\middlewares\user_context.py", line 56, in __call__
    return await handler(event, data)
  File "C:\Users\комп\AppData\Local\Programs\Python\Python310\lib\site-packages\aiogram\fsm\middleware.py", line 42, in __call__
    return await handler(event, data)
  File "C:\Users\комп\AppData\Local\Programs\Python\Python310\lib\site-packages\aiogram\dispatcher\event\telegram.py", line 121, in trigger
    return await wrapped_inner(event, kwargs)
  File "C:\Users\комп\AppData\Local\Programs\Python\Python310\lib\site-packages\aiogram\dispatcher\event\handler.py", line 43, in call
    return await wrapped()
  File "C:\Users\комп\AppData\Local\Programs\Python\Python310\lib\site-packages\aiogram\dispatcher\dispatcher.py", line 276, in _listen_update
    return await self.propagate_event(update_type=update_type, event=event, **kwargs)
  File "C:\Users\комп\AppData\Local\Programs\Python\Python310\lib\site-packages\aiogram\dispatcher\router.py", line 146, in propagate_event
    return await observer.wrap_outer_middleware(_wrapped, event=event, data=kwargs)
  File "C:\Users\комп\AppData\Local\Programs\Python\Python310\lib\site-packages\aiogram\dispatcher\router.py", line 141, in _wrapped
    return await self._propagate_event(
  File "C:\Users\комп\AppData\Local\Programs\Python\Python310\lib\site-packages\aiogram\dispatcher\router.py", line 166, in _propagate_event
    response = await observer.trigger(event, **kwargs)
  File "C:\Users\комп\AppData\Local\Programs\Python\Python310\lib\site-packages\aiogram\dispatcher\event\telegram.py", line 121, in trigger
    return await wrapped_inner(event, kwargs)
  File "C:\Users\комп\AppData\Local\Programs\Python\Python310\lib\site-packages\aiogram\dispatcher\event\handler.py", line 43, in call
    return await wrapped()
  File "c:\Users\комп\Desktop\Gamma_m_Project\Gamma_M_infoBot\main.py", line 148, in back_to_workshop
    await call.message.edit_text('Выберите цех:', reply_markup=start_keyboard)
  File "C:\Users\комп\AppData\Local\Programs\Python\Python310\lib\site-packages\aiogram\types\message.py", line 3670, in edit_text
    return EditMessageText(
  File "C:\Users\комп\AppData\Local\Programs\Python\Python310\lib\site-packages\pydantic\main.py", line 214, in __init__
    validated_self = self.__pydantic_validator__.validate_python(data, self_instance=self)
pydantic_core._pydantic_core.ValidationError: 1 validation error for EditMessageText
reply_markup
  Input should be a valid dictionary or instance of InlineKeyboardMarkup [type=model_type, input_value=ReplyKeyboardMarkup(keybo...er=None, selective=None), input_type=ReplyKeyboardMarkup]
    For further information visit https://errors.pydantic.dev/2.10/v/model_type
2025-02-06 11:50:33,993 - INFO - Update id=619412456 is not handled. Duration 139 ms by bot id=7735807460
2025-02-06 11:50:33,994 - ERROR - Cause exception while process update id=619412456 by bot id=7735807460
ValidationError: 1 validation error for EditMessageText
reply_markup
  Input should be a valid dictionary or instance of InlineKeyboardMarkup [type=model_type, input_value=ReplyKeyboardMarkup(keybo...er=None, selective=None), input_type=ReplyKeyboardMarkup]
    For further information visit https://errors.pydantic.dev/2.10/v/model_type
Traceback (most recent call last):
  File "C:\Users\комп\AppData\Local\Programs\Python\Python310\lib\site-packages\aiogram\dispatcher\dispatcher.py", line 309, in _process_update
    response = await self.feed_update(bot, update, **kwargs)
  File "C:\Users\комп\AppData\Local\Programs\Python\Python310\lib\site-packages\aiogram\dispatcher\dispatcher.py", line 158, in feed_update
    response = await self.update.wrap_outer_middleware(
  File "C:\Users\комп\AppData\Local\Programs\Python\Python310\lib\site-packages\aiogram\dispatcher\middlewares\error.py", line 25, in __call__
    return await handler(event, data)
  File "C:\Users\комп\AppData\Local\Programs\Python\Python310\lib\site-packages\aiogram\dispatcher\middlewares\user_context.py", line 56, in __call__
    return await handler(event, data)
  File "C:\Users\комп\AppData\Local\Programs\Python\Python310\lib\site-packages\aiogram\fsm\middleware.py", line 42, in __call__
    return await handler(event, data)
  File "C:\Users\комп\AppData\Local\Programs\Python\Python310\lib\site-packages\aiogram\dispatcher\event\telegram.py", line 121, in trigger
    return await wrapped_inner(event, kwargs)
  File "C:\Users\комп\AppData\Local\Programs\Python\Python310\lib\site-packages\aiogram\dispatcher\event\handler.py", line 43, in call
    return await wrapped()
  File "C:\Users\комп\AppData\Local\Programs\Python\Python310\lib\site-packages\aiogram\dispatcher\dispatcher.py", line 276, in _listen_update
    return await self.propagate_event(update_type=update_type, event=event, **kwargs)
  File "C:\Users\комп\AppData\Local\Programs\Python\Python310\lib\site-packages\aiogram\dispatcher\router.py", line 146, in propagate_event
    return await observer.wrap_outer_middleware(_wrapped, event=event, data=kwargs)
  File "C:\Users\комп\AppData\Local\Programs\Python\Python310\lib\site-packages\aiogram\dispatcher\router.py", line 141, in _wrapped
    return await self._propagate_event(
  File "C:\Users\комп\AppData\Local\Programs\Python\Python310\lib\site-packages\aiogram\dispatcher\router.py", line 166, in _propagate_event
    response = await observer.trigger(event, **kwargs)
  File "C:\Users\комп\AppData\Local\Programs\Python\Python310\lib\site-packages\aiogram\dispatcher\event\telegram.py", line 121, in trigger
    return await wrapped_inner(event, kwargs)
  File "C:\Users\комп\AppData\Local\Programs\Python\Python310\lib\site-packages\aiogram\dispatcher\event\handler.py", line 43, in call
    return await wrapped()
  File "c:\Users\комп\Desktop\Gamma_m_Project\Gamma_M_infoBot\main.py", line 148, in back_to_workshop
    await call.message.edit_text('Выберите цех:', reply_markup=start_keyboard)
  File "C:\Users\комп\AppData\Local\Programs\Python\Python310\lib\site-packages\aiogram\types\message.py", line 3670, in edit_text
    return EditMessageText(
  File "C:\Users\комп\AppData\Local\Programs\Python\Python310\lib\site-packages\pydantic\main.py", line 214, in __init__
    validated_self = self.__pydantic_validator__.validate_python(data, self_instance=self)
pydantic_core._pydantic_core.ValidationError: 1 validation error for EditMessageText
reply_markup
  Input should be a valid dictionary or instance of InlineKeyboardMarkup [type=model_type, input_value=ReplyKeyboardMarkup(keybo...er=None, selective=None), input_type=ReplyKeyboardMarkup]
    For further information visit https://errors.pydantic.dev/2.10/v/model_type
2025-02-06 11:50:34,206 - INFO - Update id=619412457 is not handled. Duration 250 ms by bot id=7735807460
2025-02-06 11:50:34,207 - ERROR - Cause exception while process update id=619412457 by bot id=7735807460
ValidationError: 1 validation error for EditMessageText
reply_markup
  Input should be a valid dictionary or instance of InlineKeyboardMarkup [type=model_type, input_value=ReplyKeyboardMarkup(keybo...er=None, selective=None), input_type=ReplyKeyboardMarkup]
    For further information visit https://errors.pydantic.dev/2.10/v/model_type
Traceback (most recent call last):
  File "C:\Users\комп\AppData\Local\Programs\Python\Python310\lib\site-packages\aiogram\dispatcher\dispatcher.py", line 309, in _process_update
    response = await self.feed_update(bot, update, **kwargs)
  File "C:\Users\комп\AppData\Local\Programs\Python\Python310\lib\site-packages\aiogram\dispatcher\dispatcher.py", line 158, in feed_update
    response = await self.update.wrap_outer_middleware(
  File "C:\Users\комп\AppData\Local\Programs\Python\Python310\lib\site-packages\aiogram\dispatcher\middlewares\error.py", line 25, in __call__
    return await handler(event, data)
  File "C:\Users\комп\AppData\Local\Programs\Python\Python310\lib\site-packages\aiogram\dispatcher\middlewares\user_context.py", line 56, in __call__
    return await handler(event, data)
  File "C:\Users\комп\AppData\Local\Programs\Python\Python310\lib\site-packages\aiogram\fsm\middleware.py", line 42, in __call__
    return await handler(event, data)
  File "C:\Users\комп\AppData\Local\Programs\Python\Python310\lib\site-packages\aiogram\dispatcher\event\telegram.py", line 121, in trigger
    return await wrapped_inner(event, kwargs)
  File "C:\Users\комп\AppData\Local\Programs\Python\Python310\lib\site-packages\aiogram\dispatcher\event\handler.py", line 43, in call
    return await wrapped()
  File "C:\Users\комп\AppData\Local\Programs\Python\Python310\lib\site-packages\aiogram\dispatcher\dispatcher.py", line 276, in _listen_update
    return await self.propagate_event(update_type=update_type, event=event, **kwargs)
  File "C:\Users\комп\AppData\Local\Programs\Python\Python310\lib\site-packages\aiogram\dispatcher\router.py", line 146, in propagate_event
    return await observer.wrap_outer_middleware(_wrapped, event=event, data=kwargs)
  File "C:\Users\комп\AppData\Local\Programs\Python\Python310\lib\site-packages\aiogram\dispatcher\router.py", line 141, in _wrapped
    return await self._propagate_event(
  File "C:\Users\комп\AppData\Local\Programs\Python\Python310\lib\site-packages\aiogram\dispatcher\router.py", line 166, in _propagate_event
    response = await observer.trigger(event, **kwargs)
  File "C:\Users\комп\AppData\Local\Programs\Python\Python310\lib\site-packages\aiogram\dispatcher\event\telegram.py", line 121, in trigger
    return await wrapped_inner(event, kwargs)
  File "C:\Users\комп\AppData\Local\Programs\Python\Python310\lib\site-packages\aiogram\dispatcher\event\handler.py", line 43, in call
    return await wrapped()
  File "c:\Users\комп\Desktop\Gamma_m_Project\Gamma_M_infoBot\main.py", line 148, in back_to_workshop
    await call.message.edit_text('Выберите цех:', reply_markup=start_keyboard)
  File "C:\Users\комп\AppData\Local\Programs\Python\Python310\lib\site-packages\aiogram\types\message.py", line 3670, in edit_text
    return EditMessageText(
  File "C:\Users\комп\AppData\Local\Programs\Python\Python310\lib\site-packages\pydantic\main.py", line 214, in __init__
    validated_self = self.__pydantic_validator__.validate_python(data, self_instance=self)
pydantic_core._pydantic_core.ValidationError: 1 validation error for EditMessageText
reply_markup
  Input should be a valid dictionary or instance of InlineKeyboardMarkup [type=model_type, input_value=ReplyKeyboardMarkup(keybo...er=None, selective=None), input_type=ReplyKeyboardMarkup]
    For further information visit https://errors.pydantic.dev/2.10/v/model_type
2025-02-06 11:50:39,233 - INFO - Update id=619412458 is not handled. Duration 63 ms by bot id=7735807460
2025-02-06 11:50:39,233 - ERROR - Cause exception while process update id=619412458 by bot id=7735807460
ValidationError: 1 validation error for EditMessageText
reply_markup
  Input should be a valid dictionary or instance of InlineKeyboardMarkup [type=model_type, input_value=ReplyKeyboardMarkup(keybo...er=None, selective=None), input_type=ReplyKeyboardMarkup]
    For further information visit https://errors.pydantic.dev/2.10/v/model_type
Traceback (most recent call last):
  File "C:\Users\комп\AppData\Local\Programs\Python\Python310\lib\site-packages\aiogram\dispatcher\dispatcher.py", line 309, in _process_update
    response = await self.feed_update(bot, update, **kwargs)
  File "C:\Users\комп\AppData\Local\Programs\Python\Python310\lib\site-packages\aiogram\dispatcher\dispatcher.py", line 158, in feed_update
    response = await self.update.wrap_outer_middleware(
  File "C:\Users\комп\AppData\Local\Programs\Python\Python310\lib\site-packages\aiogram\dispatcher\middlewares\error.py", line 25, in __call__
    return await handler(event, data)
  File "C:\Users\комп\AppData\Local\Programs\Python\Python310\lib\site-packages\aiogram\dispatcher\middlewares\user_context.py", line 56, in __call__
    return await handler(event, data)
  File "C:\Users\комп\AppData\Local\Programs\Python\Python310\lib\site-packages\aiogram\fsm\middleware.py", line 42, in __call__
    return await handler(event, data)
  File "C:\Users\комп\AppData\Local\Programs\Python\Python310\lib\site-packages\aiogram\dispatcher\event\telegram.py", line 121, in trigger
    return await wrapped_inner(event, kwargs)
  File "C:\Users\комп\AppData\Local\Programs\Python\Python310\lib\site-packages\aiogram\dispatcher\event\handler.py", line 43, in call
    return await wrapped()
  File "C:\Users\комп\AppData\Local\Programs\Python\Python310\lib\site-packages\aiogram\dispatcher\dispatcher.py", line 276, in _listen_update
    return await self.propagate_event(update_type=update_type, event=event, **kwargs)
  File "C:\Users\комп\AppData\Local\Programs\Python\Python310\lib\site-packages\aiogram\dispatcher\router.py", line 146, in propagate_event
    return await observer.wrap_outer_middleware(_wrapped, event=event, data=kwargs)
  File "C:\Users\комп\AppData\Local\Programs\Python\Python310\lib\site-packages\aiogram\dispatcher\router.py", line 141, in _wrapped
    return await self._propagate_event(
  File "C:\Users\комп\AppData\Local\Programs\Python\Python310\lib\site-packages\aiogram\dispatcher\router.py", line 166, in _propagate_event
    response = await observer.trigger(event, **kwargs)
  File "C:\Users\комп\AppData\Local\Programs\Python\Python310\lib\site-packages\aiogram\dispatcher\event\telegram.py", line 121, in trigger
    return await wrapped_inner(event, kwargs)
  File "C:\Users\комп\AppData\Local\Programs\Python\Python310\lib\site-packages\aiogram\dispatcher\event\handler.py", line 43, in call
    return await wrapped()
  File "c:\Users\комп\Desktop\Gamma_m_Project\Gamma_M_infoBot\main.py", line 148, in back_to_workshop
    await call.message.edit_text('Выберите цех:', reply_markup=start_keyboard)
  File "C:\Users\комп\AppData\Local\Programs\Python\Python310\lib\site-packages\aiogram\types\message.py", line 3670, in edit_text
    return EditMessageText(
  File "C:\Users\комп\AppData\Local\Programs\Python\Python310\lib\site-packages\pydantic\main.py", line 214, in __init__
    validated_self = self.__pydantic_validator__.validate_python(data, self_instance=self)
pydantic_core._pydantic_core.ValidationError: 1 validation error for EditMessageText
reply_markup
  Input should be a valid dictionary or instance of InlineKeyboardMarkup [type=model_type, input_value=ReplyKeyboardMarkup(keybo...er=None, selective=None), input_type=ReplyKeyboardMarkup]
    For further information visit https://errors.pydantic.dev/2.10/v/model_type
2025-02-06 11:50:39,640 - INFO - Update id=619412459 is not handled. Duration 62 ms by bot id=7735807460
2025-02-06 11:50:39,640 - ERROR - Cause exception while process update id=619412459 by bot id=7735807460
ValidationError: 1 validation error for EditMessageText
reply_markup
  Input should be a valid dictionary or instance of InlineKeyboardMarkup [type=model_type, input_value=ReplyKeyboardMarkup(keybo...er=None, selective=None), input_type=ReplyKeyboardMarkup]
    For further information visit https://errors.pydantic.dev/2.10/v/model_type
Traceback (most recent call last):
  File "C:\Users\комп\AppData\Local\Programs\Python\Python310\lib\site-packages\aiogram\dispatcher\dispatcher.py", line 309, in _process_update
    response = await self.feed_update(bot, update, **kwargs)
  File "C:\Users\комп\AppData\Local\Programs\Python\Python310\lib\site-packages\aiogram\dispatcher\dispatcher.py", line 158, in feed_update
    response = await self.update.wrap_outer_middleware(
  File "C:\Users\комп\AppData\Local\Programs\Python\Python310\lib\site-packages\aiogram\dispatcher\middlewares\error.py", line 25, in __call__
    return await handler(event, data)
  File "C:\Users\комп\AppData\Local\Programs\Python\Python310\lib\site-packages\aiogram\dispatcher\middlewares\user_context.py", line 56, in __call__
    return await handler(event, data)
  File "C:\Users\комп\AppData\Local\Programs\Python\Python310\lib\site-packages\aiogram\fsm\middleware.py", line 42, in __call__
    return await handler(event, data)
  File "C:\Users\комп\AppData\Local\Programs\Python\Python310\lib\site-packages\aiogram\dispatcher\event\telegram.py", line 121, in trigger
    return await wrapped_inner(event, kwargs)
  File "C:\Users\комп\AppData\Local\Programs\Python\Python310\lib\site-packages\aiogram\dispatcher\event\handler.py", line 43, in call
    return await wrapped()
  File "C:\Users\комп\AppData\Local\Programs\Python\Python310\lib\site-packages\aiogram\dispatcher\dispatcher.py", line 276, in _listen_update
    return await self.propagate_event(update_type=update_type, event=event, **kwargs)
  File "C:\Users\комп\AppData\Local\Programs\Python\Python310\lib\site-packages\aiogram\dispatcher\router.py", line 146, in propagate_event
    return await observer.wrap_outer_middleware(_wrapped, event=event, data=kwargs)
  File "C:\Users\комп\AppData\Local\Programs\Python\Python310\lib\site-packages\aiogram\dispatcher\router.py", line 141, in _wrapped
    return await self._propagate_event(
  File "C:\Users\комп\AppData\Local\Programs\Python\Python310\lib\site-packages\aiogram\dispatcher\router.py", line 166, in _propagate_event
    response = await observer.trigger(event, **kwargs)
  File "C:\Users\комп\AppData\Local\Programs\Python\Python310\lib\site-packages\aiogram\dispatcher\event\telegram.py", line 121, in trigger
    return await wrapped_inner(event, kwargs)
  File "C:\Users\комп\AppData\Local\Programs\Python\Python310\lib\site-packages\aiogram\dispatcher\event\handler.py", line 43, in call
    return await wrapped()
  File "c:\Users\комп\Desktop\Gamma_m_Project\Gamma_M_infoBot\main.py", line 148, in back_to_workshop
    await call.message.edit_text('Выберите цех:', reply_markup=start_keyboard)
  File "C:\Users\комп\AppData\Local\Programs\Python\Python310\lib\site-packages\aiogram\types\message.py", line 3670, in edit_text
    return EditMessageText(
  File "C:\Users\комп\AppData\Local\Programs\Python\Python310\lib\site-packages\pydantic\main.py", line 214, in __init__
    validated_self = self.__pydantic_validator__.validate_python(data, self_instance=self)
pydantic_core._pydantic_core.ValidationError: 1 validation error for EditMessageText
reply_markup
  Input should be a valid dictionary or instance of InlineKeyboardMarkup [type=model_type, input_value=ReplyKeyboardMarkup(keybo...er=None, selective=None), input_type=ReplyKeyboardMarkup]
    For further information visit https://errors.pydantic.dev/2.10/v/model_type
2025-02-06 11:54:19,671 - INFO - Start polling
2025-02-06 11:54:19,871 - INFO - Run polling for bot @Gamma_M_machines_information_Bot id=7735807460 - 'Gamma_M information about the machines'
2025-02-06 11:54:21,178 - INFO - Пользователь 857663686 выбрал опцию: Цех 1
2025-02-06 11:54:21,178 - INFO - Update id=619412460 is handled. Duration 844 ms by bot id=7735807460
2025-02-06 11:56:08,565 - INFO - Start polling
2025-02-06 11:56:08,758 - INFO - Run polling for bot @Gamma_M_machines_information_Bot id=7735807460 - 'Gamma_M information about the machines'
2025-02-06 11:56:31,957 - INFO - Update id=619412461 is not handled. Duration 0 ms by bot id=7735807460
2025-02-06 11:56:34,005 - INFO - Update id=619412462 is not handled. Duration 0 ms by bot id=7735807460
2025-02-06 11:56:42,601 - INFO - Update id=619412463 is not handled. Duration 0 ms by bot id=7735807460
2025-02-06 11:56:43,819 - INFO - Update id=619412464 is not handled. Duration 0 ms by bot id=7735807460
2025-02-06 11:56:53,501 - INFO - Update id=619412465 is not handled. Duration 0 ms by bot id=7735807460
2025-02-06 11:58:59,912 - INFO - Start polling
2025-02-06 11:59:00,113 - INFO - Run polling for bot @Gamma_M_machines_information_Bot id=7735807460 - 'Gamma_M information about the machines'
2025-02-06 11:59:00,212 - INFO - Update id=619412466 is not handled. Duration 0 ms by bot id=7735807460
2025-02-06 11:59:04,634 - INFO - Update id=619412467 is not handled. Duration 0 ms by bot id=7735807460
2025-02-06 11:59:05,877 - INFO - Update id=619412468 is not handled. Duration 0 ms by bot id=7735807460
2025-02-06 11:59:06,892 - INFO - Update id=619412469 is not handled. Duration 0 ms by bot id=7735807460
2025-02-06 12:00:21,059 - INFO - Пользователь 857663686 начал работу.
2025-02-06 12:00:21,059 - INFO - Update id=619412470 is handled. Duration 266 ms by bot id=7735807460
2025-02-06 12:00:23,997 - INFO - Update id=619412471 is not handled. Duration 625 ms by bot id=7735807460
2025-02-06 12:00:23,997 - ERROR - Cause exception while process update id=619412471 by bot id=7735807460
ValidationError: 1 validation error for InlineKeyboardMarkup
inline_keyboard
  Field required [type=missing, input_value={}, input_type=dict]
    For further information visit https://errors.pydantic.dev/2.10/v/missing
Traceback (most recent call last):
  File "C:\Users\комп\AppData\Local\Programs\Python\Python310\lib\site-packages\aiogram\dispatcher\dispatcher.py", line 309, in _process_update
    response = await self.feed_update(bot, update, **kwargs)
  File "C:\Users\комп\AppData\Local\Programs\Python\Python310\lib\site-packages\aiogram\dispatcher\dispatcher.py", line 158, in feed_update
    response = await self.update.wrap_outer_middleware(
  File "C:\Users\комп\AppData\Local\Programs\Python\Python310\lib\site-packages\aiogram\dispatcher\middlewares\error.py", line 25, in __call__
    return await handler(event, data)
  File "C:\Users\комп\AppData\Local\Programs\Python\Python310\lib\site-packages\aiogram\dispatcher\middlewares\user_context.py", line 56, in __call__
    return await handler(event, data)
  File "C:\Users\комп\AppData\Local\Programs\Python\Python310\lib\site-packages\aiogram\fsm\middleware.py", line 42, in __call__
    return await handler(event, data)
  File "C:\Users\комп\AppData\Local\Programs\Python\Python310\lib\site-packages\aiogram\dispatcher\event\telegram.py", line 121, in trigger
    return await wrapped_inner(event, kwargs)
  File "C:\Users\комп\AppData\Local\Programs\Python\Python310\lib\site-packages\aiogram\dispatcher\event\handler.py", line 43, in call
    return await wrapped()
  File "C:\Users\комп\AppData\Local\Programs\Python\Python310\lib\site-packages\aiogram\dispatcher\dispatcher.py", line 276, in _listen_update
    return await self.propagate_event(update_type=update_type, event=event, **kwargs)
  File "C:\Users\комп\AppData\Local\Programs\Python\Python310\lib\site-packages\aiogram\dispatcher\router.py", line 146, in propagate_event
    return await observer.wrap_outer_middleware(_wrapped, event=event, data=kwargs)
  File "C:\Users\комп\AppData\Local\Programs\Python\Python310\lib\site-packages\aiogram\dispatcher\router.py", line 141, in _wrapped
    return await self._propagate_event(
  File "C:\Users\комп\AppData\Local\Programs\Python\Python310\lib\site-packages\aiogram\dispatcher\router.py", line 166, in _propagate_event
    response = await observer.trigger(event, **kwargs)
  File "C:\Users\комп\AppData\Local\Programs\Python\Python310\lib\site-packages\aiogram\dispatcher\event\telegram.py", line 121, in trigger
    return await wrapped_inner(event, kwargs)
  File "C:\Users\комп\AppData\Local\Programs\Python\Python310\lib\site-packages\aiogram\dispatcher\event\handler.py", line 43, in call
    return await wrapped()
  File "c:\Users\комп\Desktop\Gamma_m_Project\Gamma_M_infoBot\main.py", line 107, in choise_workshop
    machine_keyboard = get_machine_keyboard(machines)
  File "c:\Users\комп\Desktop\Gamma_m_Project\Gamma_M_infoBot\main.py", line 47, in get_machine_keyboard
    keyboard = InlineKeyboardMarkup()
  File "C:\Users\комп\AppData\Local\Programs\Python\Python310\lib\site-packages\pydantic\main.py", line 214, in __init__
    validated_self = self.__pydantic_validator__.validate_python(data, self_instance=self)
pydantic_core._pydantic_core.ValidationError: 1 validation error for InlineKeyboardMarkup
inline_keyboard
  Field required [type=missing, input_value={}, input_type=dict]
    For further information visit https://errors.pydantic.dev/2.10/v/missing
2025-02-06 12:00:24,997 - ERROR - В файле workshop 2.xlsx отсутствует столбец 'Машина'.
2025-02-06 12:00:24,997 - INFO - Update id=619412472 is handled. Duration 125 ms by bot id=7735807460
2025-02-06 12:00:25,475 - ERROR - В файле workshop 3.xlsx отсутствует столбец 'Машина'.
2025-02-06 12:00:25,475 - INFO - Update id=619412473 is handled. Duration 110 ms by bot id=7735807460
2025-02-06 12:00:26,653 - INFO - Update id=619412474 is not handled. Duration 31 ms by bot id=7735807460
2025-02-06 12:00:26,653 - ERROR - Cause exception while process update id=619412474 by bot id=7735807460
ValidationError: 1 validation error for InlineKeyboardMarkup
inline_keyboard
  Field required [type=missing, input_value={}, input_type=dict]
    For further information visit https://errors.pydantic.dev/2.10/v/missing
Traceback (most recent call last):
  File "C:\Users\комп\AppData\Local\Programs\Python\Python310\lib\site-packages\aiogram\dispatcher\dispatcher.py", line 309, in _process_update
    response = await self.feed_update(bot, update, **kwargs)
  File "C:\Users\комп\AppData\Local\Programs\Python\Python310\lib\site-packages\aiogram\dispatcher\dispatcher.py", line 158, in feed_update
    response = await self.update.wrap_outer_middleware(
  File "C:\Users\комп\AppData\Local\Programs\Python\Python310\lib\site-packages\aiogram\dispatcher\middlewares\error.py", line 25, in __call__
    return await handler(event, data)
  File "C:\Users\комп\AppData\Local\Programs\Python\Python310\lib\site-packages\aiogram\dispatcher\middlewares\user_context.py", line 56, in __call__
    return await handler(event, data)
  File "C:\Users\комп\AppData\Local\Programs\Python\Python310\lib\site-packages\aiogram\fsm\middleware.py", line 42, in __call__
    return await handler(event, data)
  File "C:\Users\комп\AppData\Local\Programs\Python\Python310\lib\site-packages\aiogram\dispatcher\event\telegram.py", line 121, in trigger
    return await wrapped_inner(event, kwargs)
  File "C:\Users\комп\AppData\Local\Programs\Python\Python310\lib\site-packages\aiogram\dispatcher\event\handler.py", line 43, in call
    return await wrapped()
  File "C:\Users\комп\AppData\Local\Programs\Python\Python310\lib\site-packages\aiogram\dispatcher\dispatcher.py", line 276, in _listen_update
    return await self.propagate_event(update_type=update_type, event=event, **kwargs)
  File "C:\Users\комп\AppData\Local\Programs\Python\Python310\lib\site-packages\aiogram\dispatcher\router.py", line 146, in propagate_event
    return await observer.wrap_outer_middleware(_wrapped, event=event, data=kwargs)
  File "C:\Users\комп\AppData\Local\Programs\Python\Python310\lib\site-packages\aiogram\dispatcher\router.py", line 141, in _wrapped
    return await self._propagate_event(
  File "C:\Users\комп\AppData\Local\Programs\Python\Python310\lib\site-packages\aiogram\dispatcher\router.py", line 166, in _propagate_event
    response = await observer.trigger(event, **kwargs)
  File "C:\Users\комп\AppData\Local\Programs\Python\Python310\lib\site-packages\aiogram\dispatcher\event\telegram.py", line 121, in trigger
    return await wrapped_inner(event, kwargs)
  File "C:\Users\комп\AppData\Local\Programs\Python\Python310\lib\site-packages\aiogram\dispatcher\event\handler.py", line 43, in call
    return await wrapped()
  File "c:\Users\комп\Desktop\Gamma_m_Project\Gamma_M_infoBot\main.py", line 107, in choise_workshop
    machine_keyboard = get_machine_keyboard(machines)
  File "c:\Users\комп\Desktop\Gamma_m_Project\Gamma_M_infoBot\main.py", line 47, in get_machine_keyboard
    keyboard = InlineKeyboardMarkup()
  File "C:\Users\комп\AppData\Local\Programs\Python\Python310\lib\site-packages\pydantic\main.py", line 214, in __init__
    validated_self = self.__pydantic_validator__.validate_python(data, self_instance=self)
pydantic_core._pydantic_core.ValidationError: 1 validation error for InlineKeyboardMarkup
inline_keyboard
  Field required [type=missing, input_value={}, input_type=dict]
    For further information visit https://errors.pydantic.dev/2.10/v/missing
2025-02-06 12:00:51,236 - INFO - Start polling
2025-02-06 12:00:51,424 - INFO - Run polling for bot @Gamma_M_machines_information_Bot id=7735807460 - 'Gamma_M information about the machines'
2025-02-06 12:00:51,849 - INFO - Пользователь 857663686 начал работу.
2025-02-06 12:00:51,849 - INFO - Update id=619412476 is handled. Duration 328 ms by bot id=7735807460
2025-02-06 12:00:51,849 - INFO - Пользователь 857663686 начал работу.
2025-02-06 12:00:51,849 - INFO - Update id=619412475 is handled. Duration 328 ms by bot id=7735807460
2025-02-06 12:00:55,100 - INFO - Пользователь 857663686 выбрал опцию: Цех 1
2025-02-06 12:00:55,100 - INFO - Update id=619412477 is handled. Duration 875 ms by bot id=7735807460
2025-02-06 12:04:28,708 - INFO - Start polling
2025-02-06 12:04:28,935 - INFO - Run polling for bot @Gamma_M_machines_information_Bot id=7735807460 - 'Gamma_M information about the machines'
2025-02-06 12:04:29,324 - INFO - Пользователь 857663686 начал работу.
2025-02-06 12:04:29,324 - INFO - Update id=619412478 is handled. Duration 296 ms by bot id=7735807460
2025-02-06 12:04:34,290 - INFO - Пользователь 857663686 выбрал опцию: Цех 1
2025-02-06 12:04:34,290 - INFO - Update id=619412479 is handled. Duration 906 ms by bot id=7735807460
2025-02-06 12:04:36,521 - INFO - Update id=619412480 is handled. Duration 140 ms by bot id=7735807460
2025-02-06 12:04:37,774 - ERROR - В файле workshop 2.xlsx отсутствует столбец 'Машина'.
2025-02-06 12:04:37,775 - INFO - Update id=619412481 is handled. Duration 156 ms by bot id=7735807460
2025-02-06 12:04:39,533 - INFO - Пользователь 857663686 выбрал опцию: Цех 1
2025-02-06 12:04:39,533 - INFO - Update id=619412482 is handled. Duration 171 ms by bot id=7735807460
2025-02-06 12:04:40,963 - INFO - Update id=619412483 is handled. Duration 93 ms by bot id=7735807460
2025-02-06 12:04:45,466 - INFO - Update id=619412484 is handled. Duration 78 ms by bot id=7735807460
2025-02-06 12:04:50,662 - INFO - Update id=619412485 is not handled. Duration 0 ms by bot id=7735807460
2025-02-06 12:04:51,864 - INFO - Пользователь 857663686 начал работу.
2025-02-06 12:04:51,865 - INFO - Update id=619412486 is handled. Duration 188 ms by bot id=7735807460
2025-02-06 12:04:53,437 - INFO - Пользователь 857663686 выбрал опцию: Цех 1
2025-02-06 12:04:53,437 - INFO - Update id=619412487 is handled. Duration 188 ms by bot id=7735807460
2025-02-06 12:04:55,122 - INFO - Update id=619412488 is handled. Duration 93 ms by bot id=7735807460
2025-02-06 12:08:48,299 - INFO - Пользователь 5890753417 начал работу.
2025-02-06 12:08:48,299 - INFO - Update id=619412489 is handled. Duration 93 ms by bot id=7735807460
2025-02-06 12:08:49,734 - INFO - Пользователь 5890753417 выбрал опцию: Цех 1
2025-02-06 12:08:49,734 - INFO - Update id=619412490 is handled. Duration 171 ms by bot id=7735807460
2025-02-06 12:08:55,291 - INFO - Update id=619412491 is handled. Duration 93 ms by bot id=7735807460
2025-02-06 12:09:02,754 - INFO - Пользователь 5890753417 начал работу.
2025-02-06 12:09:02,754 - INFO - Update id=619412492 is handled. Duration 139 ms by bot id=7735807460
2025-02-06 12:09:03,898 - INFO - Пользователь 5890753417 выбрал опцию: Цех 1
2025-02-06 12:09:03,899 - INFO - Update id=619412493 is handled. Duration 141 ms by bot id=7735807460
2025-02-06 12:09:05,389 - INFO - Update id=619412494 is handled. Duration 187 ms by bot id=7735807460
2025-02-06 12:09:06,191 - ERROR - В файле workshop 2.xlsx отсутствует столбец 'Машина'.
2025-02-06 12:09:06,191 - INFO - Update id=619412495 is handled. Duration 141 ms by bot id=7735807460
2025-02-06 12:09:07,816 - INFO - Пользователь 5890753417 начал работу.
2025-02-06 12:09:07,817 - INFO - Update id=619412496 is handled. Duration 125 ms by bot id=7735807460
2025-02-06 12:09:08,943 - INFO - Пользователь 5890753417 выбрал опцию: Цех 1
2025-02-06 12:09:08,944 - INFO - Update id=619412497 is handled. Duration 203 ms by bot id=7735807460
2025-02-06 12:09:10,019 - INFO - Update id=619412498 is handled. Duration 140 ms by bot id=7735807460
2025-02-06 12:09:11,478 - INFO - Пользователь 5890753417 начал работу.
2025-02-06 12:09:11,478 - INFO - Update id=619412499 is handled. Duration 141 ms by bot id=7735807460
2025-02-06 12:09:12,372 - ERROR - В файле workshop 4.xlsx отсутствует столбец 'Машина'.
2025-02-06 12:09:12,373 - INFO - Update id=619412500 is handled. Duration 125 ms by bot id=7735807460
2025-02-06 12:09:14,191 - INFO - Пользователь 5890753417 начал работу.
2025-02-06 12:09:14,191 - INFO - Update id=619412501 is handled. Duration 94 ms by bot id=7735807460
2025-02-06 12:09:15,099 - ERROR - В файле workshop 2.xlsx отсутствует столбец 'Машина'.
2025-02-06 12:09:15,100 - INFO - Update id=619412502 is handled. Duration 125 ms by bot id=7735807460
2025-02-06 12:09:17,526 - INFO - Пользователь 5890753417 начал работу.
2025-02-06 12:09:17,526 - INFO - Update id=619412503 is handled. Duration 93 ms by bot id=7735807460
2025-02-06 12:09:18,343 - INFO - Пользователь 5890753417 выбрал опцию: Цех 1
2025-02-06 12:09:18,344 - INFO - Update id=619412504 is handled. Duration 140 ms by bot id=7735807460
2025-02-06 12:09:19,282 - INFO - Update id=619412505 is handled. Duration 171 ms by bot id=7735807460
2025-02-06 12:09:20,169 - INFO - Пользователь 5890753417 выбрал опцию: Цех 1
2025-02-06 12:09:20,169 - INFO - Update id=619412506 is handled. Duration 125 ms by bot id=7735807460
2025-02-06 12:09:21,208 - INFO - Update id=619412507 is handled. Duration 78 ms by bot id=7735807460
2025-02-06 12:09:30,494 - INFO - Пользователь 5890753417 начал работу.
2025-02-06 12:09:30,494 - INFO - Update id=619412508 is handled. Duration 203 ms by bot id=7735807460
2025-02-06 12:16:24,321 - INFO - Start polling
2025-02-06 12:16:24,533 - INFO - Run polling for bot @Gamma_M_machines_information_Bot id=7735807460 - 'Gamma_M information about the machines'
2025-02-06 12:16:24,888 - INFO - Пользователь 857663686 начал работу.
2025-02-06 12:16:24,888 - INFO - Update id=619412509 is handled. Duration 266 ms by bot id=7735807460
2025-02-06 12:16:27,447 - INFO - Пользователь 857663686 выбрал цех: Цех 1
2025-02-06 12:16:27,447 - INFO - Update id=619412510 is handled. Duration 764 ms by bot id=7735807460
2025-02-06 12:16:28,691 - INFO - Update id=619412511 is handled. Duration 78 ms by bot id=7735807460
2025-02-06 12:16:30,022 - INFO - Update id=619412512 is handled. Duration 141 ms by bot id=7735807460
2025-02-06 12:16:31,676 - INFO - Пользователь 857663686 выбрал цех: Цех 2
2025-02-06 12:16:31,677 - INFO - Update id=619412513 is handled. Duration 125 ms by bot id=7735807460
2025-02-06 12:16:33,013 - INFO - Update id=619412514 is handled. Duration 93 ms by bot id=7735807460
2025-02-06 12:16:34,291 - INFO - Пользователь 857663686 выбрал цех: Цех 3
2025-02-06 12:16:34,291 - INFO - Update id=619412515 is handled. Duration 125 ms by bot id=7735807460
2025-02-06 12:16:34,947 - INFO - Update id=619412516 is handled. Duration 187 ms by bot id=7735807460
2025-02-06 12:16:35,773 - INFO - Пользователь 857663686 выбрал цех: Цех 4
2025-02-06 12:16:35,773 - INFO - Update id=619412517 is handled. Duration 141 ms by bot id=7735807460
2025-02-06 12:16:36,380 - INFO - Update id=619412518 is handled. Duration 92 ms by bot id=7735807460
2025-02-06 12:16:39,334 - INFO - Пользователь 857663686 выбрал цех: Цех 3
2025-02-06 12:16:39,334 - INFO - Update id=619412519 is handled. Duration 156 ms by bot id=7735807460
2025-02-06 12:16:40,307 - INFO - Update id=619412520 is handled. Duration 203 ms by bot id=7735807460
2025-02-06 12:16:41,136 - INFO - Update id=619412521 is handled. Duration 218 ms by bot id=7735807460
